Workbook

Sheet Final Calculation Sheet
B1: MSTC LIMITED - COMBINED BID SHEET (Auctions 21977, 21978, 21979, 21980)
A3: Quantity | B3: 1876, 1923, national e | C3: Rate | D3: Bid Sheet | E3: Unit | F3: Lot No. | G3: Buyer | H3: Mat. Value | I3: GST | J3: Mat. Value + GST | K3: TCS | L3: TDS u/s 194(O) | M3: Service Charge to MSTC | N3: TDS u/s 194(H) | O3: Net Service Charge (post TDS 194H) | P3: Service charge to MSTC | Q3: GST TDS Rate | R3: GST TDS | S3: Total Receivables in Cash | T3: Security Deposit (Expected) | U3: Security Deposit (Received) | V3: Date of Receipt | W3: Final Payment (Expected) | X3: Final Payment (Received) | Y3: Date of Receipt | Z3: LPP Expected | AA3: LPP Received | AB3: Date of Recepit of LPP | AC3: Total Received | AD3: Outstanding | AE3: Invoice No. | AF3: SAP Document | AG3: Doc./Invoice Date
A4: 669 | B4: Lot No. | C4: 1181 | D4: 21980 | E4: KG | F4: 1763 | G4: AL HAMD TRADE CORPORATION | H4: 790089 | I4: =ROUND(H4*18%,0) -> 142,216 | J4: =+H4+I4 -> 932,305 | K4: =ROUND((H4+I4)*2%,0) -> 18,646 | L4: =H4*0.1% -> 790 | M4: =H4*2.25%*118% -> 20,977 | N4: =H4*2.25%*2% -> 356 | O4: =M4-N4 -> 20,621 | P4: =ROUND(O4+L4,0) -> 21,411 | Q4: 0.02 | R4: =ROUND(H4*Q4,0) -> 15,802 | S4: =ROUND(H4*117.65%-R4,0) -> 913,738 | T4: =ROUND(H4*25%,0) -> 197,522 | U4: 197522 | V4: 24.08.2026 | W4: =ROUND(H4*92.65%-R4,0) -> 716,215 | X4: 716216 | Y4: 18.08.2026 | Z4: =IF(OR(Y4="",Y4=0),H4*0.0118*CEILING((TODAY()-DATE(2026,8,22))/7,1),IF(DATE(VALUE(RIGHT(Y4,4)),VALUE(MID(Y4,4,2)),VALUE(LEFT(Y4,2)))<=DATE(2026,8,24),0,H4*0.0118*CEILING((DATE(VALUE(RIGHT(Y4,4)),VALUE(MID(Y4,4,2)),VALUE(LEFT(Y4,2)))-DATE(2026,8,22))/7,1))) -> 0 | AC4: =U4+X4+AA4 -> 913,738 | AD4: =S4-AC4 -> 0 | AE4: DR2640100029 | AF4: 1800003271 | AG4: 24.08.2026
A5: 270 | B5: Scrap of Empty oil drum | C5: 580 | D5: 21977 | E5: NO | F5: 1874 | G5: NATIONAL ENTERPRISES | H5: 156600 | I5: =ROUND(H5*18%,0) -> 28,188 | J5: =+H5+I5 -> 184,788 | K5: =ROUND((H5+I5)*2%,0) -> 3,696 | L5: =H5*0.1% -> 157 | M5: =H5*2.25%*118% -> 4,158 | N5: =H5*2.25%*2% -> 70 | O5: =M5-N5 -> 4,087 | P5: =ROUND(O5+L5,0) -> 4,244 | Q5: 0 | R5: =ROUND(H5*Q5,0) -> 0 | S5: =ROUND(H5*117.65%-R5,0) -> 184,240 | T5: =ROUND(H5*25%,0) -> 39,150 | U5: =+T5 -> 39,150 | V5: 13.08.2026 | W5: =ROUND(H5*92.65%-R5,0) -> 145,090 | X5: 145090 | Y5: 24.08.2026 | Z5: =IF(OR(Y5="",Y5=0),H5*0.0118*CEILING((TODAY()-DATE(2026,8,22))/7,1),IF(DATE(VALUE(RIGHT(Y5,4)),VALUE(MID(Y5,4,2)),VALUE(LEFT(Y5,2)))<=DATE(2026,8,24),0,H5*0.0118*CEILING((DATE(VALUE(RIGHT(Y5,4)),VALUE(MID(Y5,4,2)),VALUE(LEFT(Y5,2)))-DATE(2026,8,22))/7,1))) -> 0 | AC5: =U5+X5+AA5 -> 184,240 | AD5: =S5-AC5 -> 0 | AE5: DR2640100030 | AF5: 1800003302 | AG5: 27.08.2026
A6: 28 | B6: Scrap of Copper of faulty AC compressor | C6: 1456 | D6: 21977 | E6: KG | F6: 1875 | G6: F R KHANS ENTERPRISES | H6: 40768 | I6: =ROUND(H6*18%,0) -> 7,338 | J6: =+H6+I6 -> 48,106 | K6: =ROUND((H6+I6)*2%,0) -> 962 | L6: =H6*0.1% -> 41 | M6: =H6*2.25%*118% -> 1,082 | N6: =H6*2.25%*2% -> 18 | O6: =M6-N6 -> 1,064 | P6: =ROUND(O6+L6,0) -> 1,105 | Q6: 0 | R6: =ROUND(H6*Q6,0) -> 0 | S6: =ROUND(H6*117.65%-R6,0) -> 47,964 | T6: =ROUND(H6*25%,0) -> 10,192 | U6: 10192 | V6: 11.08.2026 | W6: =ROUND(H6*92.65%-R6,0) -> 37,772 | X6: =+W6+R6 -> 37,772 | Y6: 20.08.2026 | Z6: =IF(OR(Y6="",Y6=0),H6*0.0118*CEILING((TODAY()-DATE(2026,8,22))/7,1),IF(DATE(VALUE(RIGHT(Y6,4)),VALUE(MID(Y6,4,2)),VALUE(LEFT(Y6,2)))<=DATE(2026,8,24),0,H6*0.0118*CEILING((DATE(VALUE(RIGHT(Y6,4)),VALUE(MID(Y6,4,2)),VALUE(LEFT(Y6,2)))-DATE(2026,8,22))/7,1))) -> 0 | AC6: =U6+X6+AA6 -> 47,964 | AD6: =S6-AC6 -> 0 | AE6: DR2640100047 | AF6: 1800003346 | AG6: 27.08.2026
A7: 3000 | B7: Scrap of MS (extracted from equip cage and empty Sf6 gas cylinder) | C7: 66 | D7: 21977 | E7: KG | F7: 1876 | G7: F R KHANS ENTERPRISES | H7: 198000 | I7: =ROUND(H7*18%,0) -> 35,640 | J7: =+H7+I7 -> 233,640 | K7: =ROUND((H7+I7)*2%,0) -> 4,673 | L7: =H7*0.1% -> 198 | M7: =H7*2.25%*118% -> 5,257 | N7: =H7*2.25%*2% -> 89 | O7: =M7-N7 -> 5,168 | P7: =ROUND(O7+L7,0) -> 5,366 | Q7: 0 | R7: =ROUND(H7*Q7,0) -> 0 | S7: =ROUND(H7*117.65%-R7,0) -> 232,947 | T7: =ROUND(H7*25%,0) -> 49,500 | U7: 49500 | V7: 11.08.2026 | W7: =ROUND(H7*92.65%-R7,0) -> 183,447 | X7: =+W7+R7-1 -> 183,446 | Y7: 20.08.2026 | Z7: =IF(OR(Y7="",Y7=0),H7*0.0118*CEILING((TODAY()-DATE(2026,8,22))/7,1),IF(DATE(VALUE(RIGHT(Y7,4)),VALUE(MID(Y7,4,2)),VALUE(LEFT(Y7,2)))<=DATE(2026,8,24),0,H7*0.0118*CEILING((DATE(VALUE(RIGHT(Y7,4)),VALUE(MID(Y7,4,2)),VALUE(LEFT(Y7,2)))-DATE(2026,8,22))/7,1))) -> 0 | AC7: =U7+X7+AA7 -> 232,946 | AD7: =S7-AC7 -> 1 | AE7: DR2640100048 | AF7: 1800003347 | AG7: 27.08.2026
A8: 7253 | B8: SCRAP ACSR CONDUCTORS (Conductor Pieces) | C8: 227 | D8: 21980 | E8: KG | F8: 1923 | G8: OMKAR STEELS | H8: 1646431 | I8: =ROUND(H8*18%,0) -> 296,358 | J8: =+H8+I8 -> 1,942,789 | K8: =ROUND((H8+I8)*2%,0) -> 38,856 | L8: =H8*0.1% -> 1,646 | M8: =H8*2.25%*118% -> 43,713 | N8: =H8*2.25%*2% -> 741 | O8: =M8-N8 -> 42,972 | P8: =ROUND(O8+L8,0) -> 44,618 | Q8: 0.02 | R8: =ROUND(H8*Q8,0) -> 32,929 | S8: =ROUND(H8*117.65%-R8,0) -> 1,904,097 | T8: =ROUND(H8*25%,0) -> 411,608 | U8: =+T8 -> 411,608 | V8: 14.08.2026 | W8: =ROUND(H8*92.65%-R8,0) -> 1,492,489 | X8: 1492490 | Y8: 24.08.2026 | Z8: =IF(OR(Y8="",Y8=0),H8*0.0118*CEILING((TODAY()-DATE(2026,8,22))/7,1),IF(DATE(VALUE(RIGHT(Y8,4)),VALUE(MID(Y8,4,2)),VALUE(LEFT(Y8,2)))<=DATE(2026,8,24),0,H8*0.0118*CEILING((DATE(VALUE(RIGHT(Y8,4)),VALUE(MID(Y8,4,2)),VALUE(LEFT(Y8,2)))-DATE(2026,8,22))/7,1))) -> 0 | AC8: =U8+X8+AA8 -> 1,904,098 | AD8: =S8-AC8 -> (1) | AE8: DR2640100045 | AF8: 1800003315 | AG8: 27.08.2026
A9: 1 | B9: Scrap Power Transformer | C9: 2787314 | D9: 21977 | E9: NO | F9: 1976 | G9: SHAR JAHAN TRADERS | H9: 2787314 | I9: =ROUND(H9*18%,0) -> 501,717 | J9: =+H9+I9 -> 3,289,031 | K9: =ROUND((H9+I9)*2%,0) -> 65,781 | L9: =H9*0.1% -> 2,787 | M9: =H9*2.25%*118% -> 74,003 | N9: =H9*2.25%*2% -> 1,254 | O9: =M9-N9 -> 72,749 | P9: =ROUND(O9+L9,0) -> 75,536 | Q9: 0 | R9: =ROUND(H9*Q9,0) -> 0 | S9: =ROUND(H9*117.65%-R9,0) -> 3,279,275 | T9: =ROUND(H9*25%,0) -> 696,829 | U9: =+T9 -> 696,829 | V9: 13.08.2026 | W9: =ROUND(H9*92.65%-R9,0) -> 2,582,446 | X9: 2582447.1 | Y9: 13.08.2026 | Z9: =IF(OR(Y9="",Y9=0),H9*0.0118*CEILING((TODAY()-DATE(2026,8,22))/7,1),IF(DATE(VALUE(RIGHT(Y9,4)),VALUE(MID(Y9,4,2)),VALUE(LEFT(Y9,2)))<=DATE(2026,8,24),0,H9*0.0118*CEILING((DATE(VALUE(RIGHT(Y9,4)),VALUE(MID(Y9,4,2)),VALUE(LEFT(Y9,2)))-DATE(2026,8,22))/7,1))) -> 0 | AC9: =U9+X9+AA9 -> 3,279,276 | AD9: =S9-AC9 -> (1) | AE9: DR2640100023 | AF9: 1800003194 | AG9: 17.08.2026
A10: 4 | B10: Scrap of 132 KV CT | C10: 51511 | D10: 21977 | E10: NO | F10: 2002 | G10: NATIONAL ENTERPRISES | H10: 206044 | I10: =ROUND(H10*18%,0) -> 37,088 | J10: =+H10+I10 -> 243,132 | K10: =ROUND((H10+I10)*2%,0) -> 4,863 | L10: =H10*0.1% -> 206 | M10: =H10*2.25%*118% -> 5,470 | N10: =H10*2.25%*2% -> 93 | O10: =M10-N10 -> 5,378 | P10: =ROUND(O10+L10,0) -> 5,584 | Q10: 0 | R10: =ROUND(H10*Q10,0) -> 0 | S10: =ROUND(H10*117.65%-R10,0) -> 242,411 | T10: =ROUND(H10*25%,0) -> 51,511 | U10: =+T10 -> 51,511 | V10: 13.08.2026 | W10: =ROUND(H10*92.65%-R10,0) -> 190,900 | X10: 190900 | Y10: 24.08.2026 | Z10: =IF(OR(Y10="",Y10=0),H10*0.0118*CEILING((TODAY()-DATE(2026,8,22))/7,1),IF(DATE(VALUE(RIGHT(Y10,4)),VALUE(MID(Y10,4,2)),VALUE(LEFT(Y10,2)))<=DATE(2026,8,24),0,H10*0.0118*CEILING((DATE(VALUE(RIGHT(Y10,4)),VALUE(MID(Y10,4,2)),VALUE(LEFT(Y10,2)))-DATE(2026,8,22))/7,1))) -> 0 | AC10: =U10+X10+AA10 -> 242,411 | AD10: =S10-AC10 -> 0 | AE10: DR2640100031 | AF10: 1800003303 | AG10: 27.08.2026
A11: 1 | B11: Scrap of 145 KV CB | C11: 65007 | D11: 21977 | E11: NO | F11: 2003 | G11: NATIONAL ENTERPRISES | H11: 65007 | I11: =ROUND(H11*18%,0) -> 11,701 | J11: =+H11+I11 -> 76,708 | K11: =ROUND((H11+I11)*2%,0) -> 1,534 | L11: =H11*0.1% -> 65 | M11: =H11*2.25%*118% -> 1,726 | N11: =H11*2.25%*2% -> 29 | O11: =M11-N11 -> 1,697 | P11: =ROUND(O11+L11,0) -> 1,762 | Q11: 0 | R11: =ROUND(H11*Q11,0) -> 0 | S11: =ROUND(H11*117.65%-R11,0) -> 76,481 | T11: =ROUND(H11*25%,0) -> 16,252 | U11: =+T11 -> 16,252 | V11: 13.08.2026 | W11: =ROUND(H11*92.65%-R11,0) -> 60,229 | X11: 60229 | Y11: 24.08.2026 | Z11: =IF(OR(Y11="",Y11=0),H11*0.0118*CEILING((TODAY()-DATE(2026,8,22))/7,1),IF(DATE(VALUE(RIGHT(Y11,4)),VALUE(MID(Y11,4,2)),VALUE(LEFT(Y11,2)))<=DATE(2026,8,24),0,H11*0.0118*CEILING((DATE(VALUE(RIGHT(Y11,4)),VALUE(MID(Y11,4,2)),VALUE(LEFT(Y11,2)))-DATE(2026,8,22))/7,1))) -> 0 | AC11: =U11+X11+AA11 -> 76,481 | AD11: =S11-AC11 -> 0 | AE11: DR2640100032 | AF11: 1800003304 | AG11: 27.08.2026
A12: 1 | B12: Scrap of 220KV CT | C12: 70006 | D12: 21977 | E12: NO | F12: 2005 | G12: NATIONAL ENTERPRISES | H12: 70006 | I12: =ROUND(H12*18%,0) -> 12,601 | J12: =+H12+I12 -> 82,607 | K12: =ROUND((H12+I12)*2%,0) -> 1,652 | L12: =H12*0.1% -> 70 | M12: =H12*2.25%*118% -> 1,859 | N12: =H12*2.25%*2% -> 32 | O12: =M12-N12 -> 1,827 | P12: =ROUND(O12+L12,0) -> 1,897 | Q12: 0 | R12: =ROUND(H12*Q12,0) -> 0 | S12: =ROUND(H12*117.65%-R12,0) -> 82,362 | T12: =ROUND(H12*25%,0) -> 17,502 | U12: =+T12 -> 17,502 | V12: 13.08.2026 | W12: =ROUND(H12*92.65%-R12,0) -> 64,861 | X12: 64859 | Y12: 24.08.2026 | Z12: =IF(OR(Y12="",Y12=0),H12*0.0118*CEILING((TODAY()-DATE(2026,8,22))/7,1),IF(DATE(VALUE(RIGHT(Y12,4)),VALUE(MID(Y12,4,2)),VALUE(LEFT(Y12,2)))<=DATE(2026,8,24),0,H12*0.0118*CEILING((DATE(VALUE(RIGHT(Y12,4)),VALUE(MID(Y12,4,2)),VALUE(LEFT(Y12,2)))-DATE(2026,8,22))/7,1))) -> 0 | AC12: =U12+X12+AA12 -> 82,361 | AD12: =S12-AC12 -> 1 | AE12: DR2640100033 | AF12: 1800003305 | AG12: 27.08.2026
A13: 25 | B13: Scrap of empty oil drums | C13: 700 | D13: 21977 | E13: NO | F13: 2006 | G13: STERLING ENTERPRISES | H13: 17500 | I13: =ROUND(H13*18%,0) -> 3,150 | J13: =+H13+I13 -> 20,650 | K13: =ROUND((H13+I13)*2%,0) -> 413 | L13: =H13*0.1% -> 18 | M13: =H13*2.25%*118% -> 465 | N13: =H13*2.25%*2% -> 8 | O13: =M13-N13 -> 457 | P13: =ROUND(O13+L13,0) -> 474 | Q13: 0 | R13: =ROUND(H13*Q13,0) -> 0 | S13: =ROUND(H13*117.65%-R13,0) -> 20,589 | T13: =ROUND(H13*25%,0) -> 4,375 | U13: 4375 | V13: 11.08.2026 | W13: =ROUND(H13*92.65%-R13,0) -> 16,214 | X13: 16214 | Y13: 11.08.2026 | Z13: =IF(OR(Y13="",Y13=0),H13*0.0118*CEILING((TODAY()-DATE(2026,8,22))/7,1),IF(DATE(VALUE(RIGHT(Y13,4)),VALUE(MID(Y13,4,2)),VALUE(LEFT(Y13,2)))<=DATE(2026,8,24),0,H13*0.0118*CEILING((DATE(VALUE(RIGHT(Y13,4)),VALUE(MID(Y13,4,2)),VALUE(LEFT(Y13,2)))-DATE(2026,8,22))/7,1))) -> 0 | AC13: =U13+X13+AA13 -> 20,589 | AD13: =S13-AC13 -> 0 | AE13: DR2640100018 | AF13: 1800003156 | AG13: 14.08.2026
A14: 1 | B14: SCRAP POWER TRANSFORMER | C14: 3857116 | D14: 21977 | E14: NO | F14: 2007 | G14: SHAR JAHAN TRADERS | H14: 3857116 | I14: =ROUND(H14*18%,0) -> 694,281 | J14: =+H14+I14 -> 4,551,397 | K14: =ROUND((H14+I14)*2%,0) -> 91,028 | L14: =H14*0.1% -> 3,857 | M14: =H14*2.25%*118% -> 102,406 | N14: =H14*2.25%*2% -> 1,736 | O14: =M14-N14 -> 100,671 | P14: =ROUND(O14+L14,0) -> 104,528 | Q14: 0 | R14: =ROUND(H14*Q14,0) -> 0 | S14: =ROUND(H14*117.65%-R14,0) -> 4,537,897 | T14: =ROUND(H14*25%,0) -> 964,279 | U14: =+T14 -> 964,279 | V14: 13.08.2026 | W14: =ROUND(H14*92.65%-R14,0) -> 3,573,618 | X14: 3573618.9 | Y14: 13.08.2026 | Z14: =IF(OR(Y14="",Y14=0),H14*0.0118*CEILING((TODAY()-DATE(2026,8,22))/7,1),IF(DATE(VALUE(RIGHT(Y14,4)),VALUE(MID(Y14,4,2)),VALUE(LEFT(Y14,2)))<=DATE(2026,8,24),0,H14*0.0118*CEILING((DATE(VALUE(RIGHT(Y14,4)),VALUE(MID(Y14,4,2)),VALUE(LEFT(Y14,2)))-DATE(2026,8,22))/7,1))) -> 0 | AC14: =U14+X14+AA14 -> 4,537,898 | AD14: =S14-AC14 -> (1) | AE14: DR2640100024 | AF14: 1800003196 | AG14: 17.08.2026
A15: 250 | B15: Scrap of empty oil Druam | C15: 543 | D15: 21977 | E15: NO | F15: 2008 | G15: HIND TRADERS | H15: 135750 | I15: =ROUND(H15*18%,0) -> 24,435 | J15: =+H15+I15 -> 160,185 | K15: =ROUND((H15+I15)*2%,0) -> 3,204 | L15: =H15*0.1% -> 136 | M15: =H15*2.25%*118% -> 3,604 | N15: =H15*2.25%*2% -> 61 | O15: =M15-N15 -> 3,543 | P15: =ROUND(O15+L15,0) -> 3,679 | Q15: 0 | R15: =ROUND(H15*Q15,0) -> 0 | S15: =ROUND(H15*117.65%-R15,0) -> 159,710 | T15: =ROUND(H15*25%,0) -> 33,938 | U15: 33938 | V15: 14.08.2026 | W15: =ROUND(H15*92.65%-R15,0) -> 125,772 | X15: 125772 | Y15: 18.08.2026 | Z15: =IF(OR(Y15="",Y15=0),H15*0.0118*CEILING((TODAY()-DATE(2026,8,22))/7,1),IF(DATE(VALUE(RIGHT(Y15,4)),VALUE(MID(Y15,4,2)),VALUE(LEFT(Y15,2)))<=DATE(2026,8,24),0,H15*0.0118*CEILING((DATE(VALUE(RIGHT(Y15,4)),VALUE(MID(Y15,4,2)),VALUE(LEFT(Y15,2)))-DATE(2026,8,22))/7,1))) -> 0 | AC15: =U15+X15+AA15 -> 159,710 | AD15: =S15-AC15 -> 0 | AE15: DR2640100026 | AF15: 1800003247 | AG15: 20.08.2026
A16: 22 | B16: Scrap of empty oil Barrel | C16: 700 | D16: 21977 | E16: NO | F16: 2011 | G16: STERLING ENTERPRISES | H16: 15400 | I16: =ROUND(H16*18%,0) -> 2,772 | J16: =+H16+I16 -> 18,172 | K16: =ROUND((H16+I16)*2%,0) -> 363 | L16: =H16*0.1% -> 15 | M16: =H16*2.25%*118% -> 409 | N16: =H16*2.25%*2% -> 7 | O16: =M16-N16 -> 402 | P16: =ROUND(O16+L16,0) -> 417 | Q16: 0 | R16: =ROUND(H16*Q16,0) -> 0 | S16: =ROUND(H16*117.65%-R16,0) -> 18,118 | T16: =ROUND(H16*25%,0) -> 3,850 | U16: 3850 | V16: 11.08.2026 | W16: =ROUND(H16*92.65%-R16,0) -> 14,268 | X16: 14267 | Y16: 11.08.2026 | Z16: =IF(OR(Y16="",Y16=0),H16*0.0118*CEILING((TODAY()-DATE(2026,8,22))/7,1),IF(DATE(VALUE(RIGHT(Y16,4)),VALUE(MID(Y16,4,2)),VALUE(LEFT(Y16,2)))<=DATE(2026,8,24),0,H16*0.0118*CEILING((DATE(VALUE(RIGHT(Y16,4)),VALUE(MID(Y16,4,2)),VALUE(LEFT(Y16,2)))-DATE(2026,8,22))/7,1))) -> 0 | AC16: =U16+X16+AA16 -> 18,117 | AD16: =S16-AC16 -> 1 | AE16: DR2640100019 | AF16: 1800003157 | AG16: 14.08.2026
A17: 100 | B17: Scrap of empty oil Barrels | C17: 710 | D17: 21978 | E17: NO | F17: 2015 | G17: STERLING ENTERPRISES | H17: 71000 | I17: =ROUND(H17*18%,0) -> 12,780 | J17: =+H17+I17 -> 83,780 | K17: =ROUND((H17+I17)*2%,0) -> 1,676 | L17: =H17*0.1% -> 71 | M17: =H17*2.25%*118% -> 1,885 | N17: =H17*2.25%*2% -> 32 | O17: =M17-N17 -> 1,853 | P17: =ROUND(O17+L17,0) -> 1,924 | Q17: 0 | R17: =ROUND(H17*Q17,0) -> 0 | S17: =ROUND(H17*117.65%-R17,0) -> 83,532 | T17: =ROUND(H17*25%,0) -> 17,750 | U17: 17750 | V17: 11.08.2026 | W17: =ROUND(H17*92.65%-R17,0) -> 65,782 | X17: =+W17 -> 65,782 | Y17: 11.08.2026 | Z17: =IF(OR(Y17="",Y17=0),H17*0.0118*CEILING((TODAY()-DATE(2026,8,22))/7,1),IF(DATE(VALUE(RIGHT(Y17,4)),VALUE(MID(Y17,4,2)),VALUE(LEFT(Y17,2)))<=DATE(2026,8,24),0,H17*0.0118*CEILING((DATE(VALUE(RIGHT(Y17,4)),VALUE(MID(Y17,4,2)),VALUE(LEFT(Y17,2)))-DATE(2026,8,22))/7,1))) -> 0 | AC17: =U17+X17+AA17 -> 83,532 | AD17: =S17-AC17 -> 0 | AE17: DR2640100020 | AF17: 1800003158 | AG17: 14.08.2026
A18: 1 | B18: Scrap of 220 KV Circuit Breaker | C18: 220001 | D18: 21978 | E18: NO | F18: 2018 | G18: NATIONAL ENTERPRISES | H18: 220001 | I18: =ROUND(H18*18%,0) -> 39,600 | J18: =+H18+I18 -> 259,601 | K18: =ROUND((H18+I18)*2%,0) -> 5,192 | L18: =H18*0.1% -> 220 | M18: =H18*2.25%*118% -> 5,841 | N18: =H18*2.25%*2% -> 99 | O18: =M18-N18 -> 5,742 | P18: =ROUND(O18+L18,0) -> 5,962 | Q18: 0 | R18: =ROUND(H18*Q18,0) -> 0 | S18: =ROUND(H18*117.65%-R18,0) -> 258,831 | T18: =ROUND(H18*25%,0) -> 55,000 | U18: =+T18 -> 55,000 | V18: 13.08.2026 | W18: =ROUND(H18*92.65%-R18,0) -> 203,831 | X18: 203831 | Y18: 24.08.2026 | Z18: =IF(OR(Y18="",Y18=0),H18*0.0118*CEILING((TODAY()-DATE(2026,8,22))/7,1),IF(DATE(VALUE(RIGHT(Y18,4)),VALUE(MID(Y18,4,2)),VALUE(LEFT(Y18,2)))<=DATE(2026,8,24),0,H18*0.0118*CEILING((DATE(VALUE(RIGHT(Y18,4)),VALUE(MID(Y18,4,2)),VALUE(LEFT(Y18,2)))-DATE(2026,8,22))/7,1))) -> 0 | AC18: =U18+X18+AA18 -> 258,831 | AD18: =S18-AC18 -> 0 | AE18: DR2640100034 | AF18: 1800003306 | AG18: 27.08.2026
A19: 1 | B19: Scrap of 220 KV Circuit Breaker | C19: 210001 | D19: 21978 | E19: NO | F19: 2019 | G19: NATIONAL ENTERPRISES | H19: 210001 | I19: =ROUND(H19*18%,0) -> 37,800 | J19: =+H19+I19 -> 247,801 | K19: =ROUND((H19+I19)*2%,0) -> 4,956 | L19: =H19*0.1% -> 210 | M19: =H19*2.25%*118% -> 5,576 | N19: =H19*2.25%*2% -> 95 | O19: =M19-N19 -> 5,481 | P19: =ROUND(O19+L19,0) -> 5,691 | Q19: 0 | R19: =ROUND(H19*Q19,0) -> 0 | S19: =ROUND(H19*117.65%-R19,0) -> 247,066 | T19: =ROUND(H19*25%,0) -> 52,500 | U19: =+T19 -> 52,500 | V19: 13.08.2026 | W19: =ROUND(H19*92.65%-R19,0) -> 194,566 | X19: 194566 | Y19: 24.08.2026 | Z19: =IF(OR(Y19="",Y19=0),H19*0.0118*CEILING((TODAY()-DATE(2026,8,22))/7,1),IF(DATE(VALUE(RIGHT(Y19,4)),VALUE(MID(Y19,4,2)),VALUE(LEFT(Y19,2)))<=DATE(2026,8,24),0,H19*0.0118*CEILING((DATE(VALUE(RIGHT(Y19,4)),VALUE(MID(Y19,4,2)),VALUE(LEFT(Y19,2)))-DATE(2026,8,22))/7,1))) -> 0 | AC19: =U19+X19+AA19 -> 247,066 | AD19: =S19-AC19 -> 0 | AE19: DR2640100035 | AF19: 1800003307 | AG19: 27.08.2026
A20: 3500 | B20: SCRAP 80MM² AAAC EARTHWIRE | C20: 333 | D20: 21978 | E20: KG | F20: 2020 | G20: OMKAR STEELS | H20: 1165500 | I20: =ROUND(H20*18%,0) -> 209,790 | J20: =+H20+I20 -> 1,375,290 | K20: =ROUND((H20+I20)*2%,0) -> 27,506 | L20: =H20*0.1% -> 1,166 | M20: =H20*2.25%*118% -> 30,944 | N20: =H20*2.25%*2% -> 524 | O20: =M20-N20 -> 30,420 | P20: =ROUND(O20+L20,0) -> 31,585 | Q20: 0.02 | R20: =ROUND(H20*Q20,0) -> 23,310 | S20: =ROUND(H20*117.65%-R20,0) -> 1,347,901 | T20: =ROUND(H20*25%,0) -> 291,375 | U20: 291375 | V20: 10.08.2026 | W20: =ROUND(H20*92.65%-R20,0) -> 1,056,526 | X20: 1056525 | Y20: 10.08.2026 | Z20: =IF(OR(Y20="",Y20=0),H20*0.0118*CEILING((TODAY()-DATE(2026,8,22))/7,1),IF(DATE(VALUE(RIGHT(Y20,4)),VALUE(MID(Y20,4,2)),VALUE(LEFT(Y20,2)))<=DATE(2026,8,24),0,H20*0.0118*CEILING((DATE(VALUE(RIGHT(Y20,4)),VALUE(MID(Y20,4,2)),VALUE(LEFT(Y20,2)))-DATE(2026,8,22))/7,1))) -> 0 | AC20: =U20+X20+AA20 -> 1,347,900 | AD20: =S20-AC20 -> 1 | AE20: DR2640100017 | AF20: 1800003065 | AG20: 12.08.2026
A21: 3 | B21: Scrap of 132 KV CT | C21: 110200 | D21: 21978 | E21: NO | F21: 2022 | G21: NATIONAL SCRAP AND BUILDING MATERIAL SUPPLIER | H21: 330600 | I21: =ROUND(H21*18%,0) -> 59,508 | J21: =+H21+I21 -> 390,108 | K21: =ROUND((H21+I21)*2%,0) -> 7,802 | L21: =H21*0.1% -> 331 | M21: =H21*2.25%*118% -> 8,777 | N21: =H21*2.25%*2% -> 149 | O21: =M21-N21 -> 8,629 | P21: =ROUND(O21+L21,0) -> 8,959 | Q21: 0 | R21: =ROUND(H21*Q21,0) -> 0 | S21: =ROUND(H21*117.65%-R21,0) -> 388,951 | T21: =ROUND(H21*25%,0) -> 82,650 | U21: =+T21 -> 82,650 | V21: 14.08.2026 | W21: =ROUND(H21*92.65%-R21,0) -> 306,301 | X21: 306301 | Y21: 21.08.2026 | Z21: =IF(OR(Y21="",Y21=0),H21*0.0118*CEILING((TODAY()-DATE(2026,8,22))/7,1),IF(DATE(VALUE(RIGHT(Y21,4)),VALUE(MID(Y21,4,2)),VALUE(LEFT(Y21,2)))<=DATE(2026,8,24),0,H21*0.0118*CEILING((DATE(VALUE(RIGHT(Y21,4)),VALUE(MID(Y21,4,2)),VALUE(LEFT(Y21,2)))-DATE(2026,8,22))/7,1))) -> 0 | AC21: =U21+X21+AA21 -> 388,951 | AD21: =S21-AC21 -> 0 | AE21: DR2640100028 | AF21: 1800003269 | AG21: 24.08.2026
A22: 3 | B22: Scrap of 132 KV CT | C22: 83743 | D22: 21978 | E22: NO | F22: 2023 | G22: NATIONAL ENTERPRISES | H22: 251229 | I22: =ROUND(H22*18%,0) -> 45,221 | J22: =+H22+I22 -> 296,450 | K22: =ROUND((H22+I22)*2%,0) -> 5,929 | L22: =H22*0.1% -> 251 | M22: =H22*2.25%*118% -> 6,670 | N22: =H22*2.25%*2% -> 113 | O22: =M22-N22 -> 6,557 | P22: =ROUND(O22+L22,0) -> 6,808 | Q22: 0 | R22: =ROUND(H22*Q22,0) -> 0 | S22: =ROUND(H22*117.65%-R22,0) -> 295,571 | T22: =ROUND(H22*25%,0) -> 62,807 | U22: =+T22 -> 62,807 | V22: 13.08.2026 | W22: =ROUND(H22*92.65%-R22,0) -> 232,764 | X22: 232764 | Y22: 24.08.2026 | Z22: =IF(OR(Y22="",Y22=0),H22*0.0118*CEILING((TODAY()-DATE(2026,8,22))/7,1),IF(DATE(VALUE(RIGHT(Y22,4)),VALUE(MID(Y22,4,2)),VALUE(LEFT(Y22,2)))<=DATE(2026,8,24),0,H22*0.0118*CEILING((DATE(VALUE(RIGHT(Y22,4)),VALUE(MID(Y22,4,2)),VALUE(LEFT(Y22,2)))-DATE(2026,8,22))/7,1))) -> 0 | AC22: =U22+X22+AA22 -> 295,571 | AD22: =S22-AC22 -> 0 | AE22: DR2640100044 | AF22: 1800003308 | AG22: 27.08.2026
A23: 90 | B23: Scrap of empty oil Barrels | C23: 700 | D23: 21978 | E23: NO | F23: 2025 | G23: STERLING ENTERPRISES | H23: 63000 | I23: =ROUND(H23*18%,0) -> 11,340 | J23: =+H23+I23 -> 74,340 | K23: =ROUND((H23+I23)*2%,0) -> 1,487 | L23: =H23*0.1% -> 63 | M23: =H23*2.25%*118% -> 1,673 | N23: =H23*2.25%*2% -> 28 | O23: =M23-N23 -> 1,644 | P23: =ROUND(O23+L23,0) -> 1,707 | Q23: 0 | R23: =ROUND(H23*Q23,0) -> 0 | S23: =ROUND(H23*117.65%-R23,0) -> 74,120 | T23: =ROUND(H23*25%,0) -> 15,750 | U23: 15750 | V23: 11.08.2026 | W23: =ROUND(H23*92.65%-R23,0) -> 58,370 | X23: 58418 | Y23: 11.08.2026 | Z23: =IF(OR(Y23="",Y23=0),H23*0.0118*CEILING((TODAY()-DATE(2026,8,22))/7,1),IF(DATE(VALUE(RIGHT(Y23,4)),VALUE(MID(Y23,4,2)),VALUE(LEFT(Y23,2)))<=DATE(2026,8,24),0,H23*0.0118*CEILING((DATE(VALUE(RIGHT(Y23,4)),VALUE(MID(Y23,4,2)),VALUE(LEFT(Y23,2)))-DATE(2026,8,22))/7,1))) -> 0 | AC23: =U23+X23+AA23 -> 74,168 | AD23: =S23-AC23 -> (48) | AE23: DR2640100021 | AF23: 1800003160 | AG23: 14.08.2026
A24: 1 | B24: Scrap of 132 KV CT | C24: 50003 | D24: 21978 | E24: NO | F24: 2027 | G24: NATIONAL ENTERPRISES | H24: 50003 | I24: =ROUND(H24*18%,0) -> 9,001 | J24: =+H24+I24 -> 59,004 | K24: =ROUND((H24+I24)*2%,0) -> 1,180 | L24: =H24*0.1% -> 50 | M24: =H24*2.25%*118% -> 1,328 | N24: =H24*2.25%*2% -> 23 | O24: =M24-N24 -> 1,305 | P24: =ROUND(O24+L24,0) -> 1,355 | Q24: 0 | R24: =ROUND(H24*Q24,0) -> 0 | S24: =ROUND(H24*117.65%-R24,0) -> 58,829 | T24: =ROUND(H24*25%,0) -> 12,501 | U24: =+T24 -> 12,501 | V24: 13.08.2026 | W24: =ROUND(H24*92.65%-R24,0) -> 46,328 | X24: 46328 | Y24: 24.08.2026 | Z24: =IF(OR(Y24="",Y24=0),H24*0.0118*CEILING((TODAY()-DATE(2026,8,22))/7,1),IF(DATE(VALUE(RIGHT(Y24,4)),VALUE(MID(Y24,4,2)),VALUE(LEFT(Y24,2)))<=DATE(2026,8,24),0,H24*0.0118*CEILING((DATE(VALUE(RIGHT(Y24,4)),VALUE(MID(Y24,4,2)),VALUE(LEFT(Y24,2)))-DATE(2026,8,22))/7,1))) -> 0 | AC24: =U24+X24+AA24 -> 58,829 | AD24: =S24-AC24 -> 0 | AE24: DR2640100036 | AF24: 1800003309 | AG24: 27.08.2026
A25: 1000 | B25: Scrap Empty Oil Drum/ Barrel | C25: 517 | D25: 21978 | E25: NO | F25: 2033 | G25: WATAN SCRAP TRADERS | H25: 517000 | I25: =ROUND(H25*18%,0) -> 93,060 | J25: =+H25+I25 -> 610,060 | K25: =ROUND((H25+I25)*2%,0) -> 12,201 | L25: =H25*0.1% -> 517 | M25: =H25*2.25%*118% -> 13,726 | N25: =H25*2.25%*2% -> 233 | O25: =M25-N25 -> 13,494 | P25: =ROUND(O25+L25,0) -> 14,011 | Q25: 0 | R25: =ROUND(H25*Q25,0) -> 0 | S25: =ROUND(H25*117.65%-R25,0) -> 608,251 | T25: =ROUND(H25*25%,0) -> 129,250 | U25: 129250 | V25: 14.08.2026 | W25: =ROUND(H25*92.65%-R25,0) -> 479,001 | X25: 479001 | Y25: 21.08.2026 | Z25: =IF(OR(Y25="",Y25=0),H25*0.0118*CEILING((TODAY()-DATE(2026,8,22))/7,1),IF(DATE(VALUE(RIGHT(Y25,4)),VALUE(MID(Y25,4,2)),VALUE(LEFT(Y25,2)))<=DATE(2026,8,24),0,H25*0.0118*CEILING((DATE(VALUE(RIGHT(Y25,4)),VALUE(MID(Y25,4,2)),VALUE(LEFT(Y25,2)))-DATE(2026,8,22))/7,1))) -> 0 | AC25: =U25+X25+AA25 -> 608,251 | AD25: =S25-AC25 -> 0 | AE25: DR2640100042 | AF25: 1800003317 | AG25: 27.08.2026
A26: 2 | B26: Scrap of 132 KV Wave Trap | C26: 14001 | D26: 21978 | E26: NO | F26: 2035 | G26: NATIONAL ENTERPRISES | H26: 28002 | I26: =ROUND(H26*18%,0) -> 5,040 | J26: =+H26+I26 -> 33,042 | K26: =ROUND((H26+I26)*2%,0) -> 661 | L26: =H26*0.1% -> 28 | M26: =H26*2.25%*118% -> 743 | N26: =H26*2.25%*2% -> 13 | O26: =M26-N26 -> 731 | P26: =ROUND(O26+L26,0) -> 759 | Q26: 0 | R26: =ROUND(H26*Q26,0) -> 0 | S26: =ROUND(H26*117.65%-R26,0) -> 32,944 | T26: =ROUND(H26*25%,0) -> 7,001 | U26: =+T26 -> 7,001 | V26: 13.08.2026 | W26: =ROUND(H26*92.65%-R26,0) -> 25,944 | X26: 25943 | Y26: 24.08.2026 | Z26: =IF(OR(Y26="",Y26=0),H26*0.0118*CEILING((TODAY()-DATE(2026,8,22))/7,1),IF(DATE(VALUE(RIGHT(Y26,4)),VALUE(MID(Y26,4,2)),VALUE(LEFT(Y26,2)))<=DATE(2026,8,24),0,H26*0.0118*CEILING((DATE(VALUE(RIGHT(Y26,4)),VALUE(MID(Y26,4,2)),VALUE(LEFT(Y26,2)))-DATE(2026,8,22))/7,1))) -> 0 | AC26: =U26+X26+AA26 -> 32,944 | AD26: =S26-AC26 -> 0 | AE26: DR2640100037 | AF26: 1800003310 | AG26: 27.08.2026
A27: 8.2 | B27: Mix Scrap (Tower angles & 0.2 ACSR Condutor pieces) | C27: 67000 | D27: 21978 | E27: MT | F27: 2036 | G27: M I SCRAP TRADERS | H27: 549400 | I27: =ROUND(H27*18%,0) -> 98,892 | J27: =+H27+I27 -> 648,292 | K27: =ROUND((H27+I27)*2%,0) -> 12,966 | L27: =H27*0.1% -> 549 | M27: =H27*2.25%*118% -> 14,587 | N27: =H27*2.25%*2% -> 247 | O27: =M27-N27 -> 14,339 | P27: =ROUND(O27+L27,0) -> 14,889 | Q27: 0.02 | R27: =ROUND(H27*Q27,0) -> 10,988 | S27: =ROUND(H27*117.65%-R27,0) -> 635,381 | T27: =ROUND(H27*25%,0) -> 137,350 | U27: 137350 | V27: 14.08.2026 | W27: =ROUND(H27*92.65%-R27,0) -> 498,031 | Y27: 0 | Z27: =IF(OR(Y27="",Y27=0),H27*0.0118*CEILING((TODAY()-DATE(2026,8,22))/7,1),IF(DATE(VALUE(RIGHT(Y27,4)),VALUE(MID(Y27,4,2)),VALUE(LEFT(Y27,2)))<=DATE(2026,8,24),0,H27*0.0118*CEILING((DATE(VALUE(RIGHT(Y27,4)),VALUE(MID(Y27,4,2)),VALUE(LEFT(Y27,2)))-DATE(2026,8,22))/7,1))) -> 19,449 | AC27: =U27+X27+AA27 -> 137,350 | AD27: =S27-AC27 -> 498,031
A28: 50 | B28: Scrap of empty oil Barrels | C28: 531 | D28: 21978 | E28: NO | F28: 2037 | G28: WATAN SCRAP TRADERS | H28: 26550 | I28: =ROUND(H28*18%,0) -> 4,779 | J28: =+H28+I28 -> 31,329 | K28: =ROUND((H28+I28)*2%,0) -> 627 | L28: =H28*0.1% -> 27 | M28: =H28*2.25%*118% -> 705 | N28: =H28*2.25%*2% -> 12 | O28: =M28-N28 -> 693 | P28: =ROUND(O28+L28,0) -> 720 | Q28: 0 | R28: =ROUND(H28*Q28,0) -> 0 | S28: =ROUND(H28*117.65%-R28,0) -> 31,236 | T28: =ROUND(H28*25%,0) -> 6,638 | U28: 6638 | V28: 14.08.2026 | W28: =ROUND(H28*92.65%-R28,0) -> 24,599 | X28: 24598 | Y28: 21.08.2026 | Z28: =IF(OR(Y28="",Y28=0),H28*0.0118*CEILING((TODAY()-DATE(2026,8,22))/7,1),IF(DATE(VALUE(RIGHT(Y28,4)),VALUE(MID(Y28,4,2)),VALUE(LEFT(Y28,2)))<=DATE(2026,8,24),0,H28*0.0118*CEILING((DATE(VALUE(RIGHT(Y28,4)),VALUE(MID(Y28,4,2)),VALUE(LEFT(Y28,2)))-DATE(2026,8,22))/7,1))) -> 0 | AC28: =U28+X28+AA28 -> 31,236 | AD28: =S28-AC28 -> 0 | AE28: DR2640100043 | AF28: 1800003318 | AG28: 27.08.2026
A29: 3 | B29: Scrap of 33 KV CT | C29: 90002 | D29: 21978 | E29: NO | F29: 2040 | G29: STERLING ENTERPRISES | H29: 270006 | I29: =ROUND(H29*18%,0) -> 48,601 | J29: =+H29+I29 -> 318,607 | K29: =ROUND((H29+I29)*2%,0) -> 6,372 | L29: =H29*0.1% -> 270 | M29: =H29*2.25%*118% -> 7,169 | N29: =H29*2.25%*2% -> 122 | O29: =M29-N29 -> 7,047 | P29: =ROUND(O29+L29,0) -> 7,317 | Q29: 0 | R29: =ROUND(H29*Q29,0) -> 0 | S29: =ROUND(H29*117.65%-R29,0) -> 317,662 | T29: =ROUND(H29*25%,0) -> 67,502 | U29: 67502 | V29: 11.08.2026 | W29: =ROUND(H29*92.65%-R29,0) -> 250,161 | Y29: 0 | Z29: =IF(OR(Y29="",Y29=0),H29*0.0118*CEILING((TODAY()-DATE(2026,8,22))/7,1),IF(DATE(VALUE(RIGHT(Y29,4)),VALUE(MID(Y29,4,2)),VALUE(LEFT(Y29,2)))<=DATE(2026,8,24),0,H29*0.0118*CEILING((DATE(VALUE(RIGHT(Y29,4)),VALUE(MID(Y29,4,2)),VALUE(LEFT(Y29,2)))-DATE(2026,8,22))/7,1))) -> 9,558 | AC29: =U29+X29+AA29 -> 67,502 | AD29: =S29-AC29 -> 250,160
A30: 5 | B30: Scrap of 132 KV CT | C30: 80000 | D30: 21979 | E30: NO | F30: 2043 | G30: NATIONAL ENTERPRISES | H30: 400000 | I30: =ROUND(H30*18%,0) -> 72,000 | J30: =+H30+I30 -> 472,000 | K30: =ROUND((H30+I30)*2%,0) -> 9,440 | L30: =H30*0.1% -> 400 | M30: =H30*2.25%*118% -> 10,620 | N30: =H30*2.25%*2% -> 180 | O30: =M30-N30 -> 10,440 | P30: =ROUND(O30+L30,0) -> 10,840 | Q30: 0 | R30: =ROUND(H30*Q30,0) -> 0 | S30: =ROUND(H30*117.65%-R30,0) -> 470,600 | T30: =ROUND(H30*25%,0) -> 100,000 | U30: =+T30 -> 100,000 | V30: 13.08.2026 | W30: =ROUND(H30*92.65%-R30,0) -> 370,600 | X30: 370600 | Y30: 24.08.2026 | Z30: =IF(OR(Y30="",Y30=0),H30*0.0118*CEILING((TODAY()-DATE(2026,8,22))/7,1),IF(DATE(VALUE(RIGHT(Y30,4)),VALUE(MID(Y30,4,2)),VALUE(LEFT(Y30,2)))<=DATE(2026,8,24),0,H30*0.0118*CEILING((DATE(VALUE(RIGHT(Y30,4)),VALUE(MID(Y30,4,2)),VALUE(LEFT(Y30,2)))-DATE(2026,8,22))/7,1))) -> 0 | AC30: =U30+X30+AA30 -> 470,600 | AD30: =S30-AC30 -> 0 | AE30: DR2640100038 | AF30: 1800003311 | AG30: 27.08.2026
A31: 670 | B31: Scrap of AAAC Earth wire | C31: 309 | D31: 21979 | E31: KG | F31: 2046 | G31: SAHARA ENTERPRISES | H31: 207030 | I31: =ROUND(H31*18%,0) -> 37,265 | J31: =+H31+I31 -> 244,295 | K31: =ROUND((H31+I31)*2%,0) -> 4,886 | L31: =H31*0.1% -> 207 | M31: =H31*2.25%*118% -> 5,497 | N31: =H31*2.25%*2% -> 93 | O31: =M31-N31 -> 5,403 | P31: =ROUND(O31+L31,0) -> 5,611 | Q31: 0 | R31: =ROUND(H31*Q31,0) -> 0 | S31: =ROUND(H31*117.65%-R31,0) -> 243,571 | T31: =ROUND(H31*25%,0) -> 51,758 | U31: 51758 | V31: 11.08.2026 | W31: =ROUND(H31*92.65%-R31,0) -> 191,813 | X31: 191812 | Y31: 21.08.2026 | Z31: =IF(OR(Y31="",Y31=0),H31*0.0118*CEILING((TODAY()-DATE(2026,8,22))/7,1),IF(DATE(VALUE(RIGHT(Y31,4)),VALUE(MID(Y31,4,2)),VALUE(LEFT(Y31,2)))<=DATE(2026,8,24),0,H31*0.0118*CEILING((DATE(VALUE(RIGHT(Y31,4)),VALUE(MID(Y31,4,2)),VALUE(LEFT(Y31,2)))-DATE(2026,8,22))/7,1))) -> 0 | AC31: =U31+X31+AA31 -> 243,570 | AD31: =S31-AC31 -> 1 | AE31: DR2640100041 | AF31: 1800003316 | AG31: 27.08.2026
A32: 2 | B32: Scrap of 220 KV CT | C32: 80006 | D32: 21979 | E32: NO | F32: 2055 | G32: NATIONAL ENTERPRISES | H32: 160012 | I32: =ROUND(H32*18%,0) -> 28,802 | J32: =+H32+I32 -> 188,814 | K32: =ROUND((H32+I32)*2%,0) -> 3,776 | L32: =H32*0.1% -> 160 | M32: =H32*2.25%*118% -> 4,248 | N32: =H32*2.25%*2% -> 72 | O32: =M32-N32 -> 4,176 | P32: =ROUND(O32+L32,0) -> 4,336 | Q32: 0 | R32: =ROUND(H32*Q32,0) -> 0 | S32: =ROUND(H32*117.65%-R32,0) -> 188,254 | T32: =ROUND(H32*25%,0) -> 40,003 | U32: =+T32 -> 40,003 | V32: 13.08.2026 | W32: =ROUND(H32*92.65%-R32,0) -> 148,251 | X32: 148251 | Y32: 24.08.2026 | Z32: =IF(OR(Y32="",Y32=0),H32*0.0118*CEILING((TODAY()-DATE(2026,8,22))/7,1),IF(DATE(VALUE(RIGHT(Y32,4)),VALUE(MID(Y32,4,2)),VALUE(LEFT(Y32,2)))<=DATE(2026,8,24),0,H32*0.0118*CEILING((DATE(VALUE(RIGHT(Y32,4)),VALUE(MID(Y32,4,2)),VALUE(LEFT(Y32,2)))-DATE(2026,8,22))/7,1))) -> 0 | AC32: =U32+X32+AA32 -> 188,254 | AD32: =S32-AC32 -> 0 | AE32: DR2640100039 | AF32: 1800003312 | AG32: 27.08.2026
A33: 1 | B33: Scrap of 33 KV GCB | C33: 29502 | D33: 21979 | E33: NO | F33: 2059 | G33: NATIONAL ENTERPRISES | H33: 29502 | I33: =ROUND(H33*18%,0) -> 5,310 | J33: =+H33+I33 -> 34,812 | K33: =ROUND((H33+I33)*2%,0) -> 696 | L33: =H33*0.1% -> 30 | M33: =H33*2.25%*118% -> 783 | N33: =H33*2.25%*2% -> 13 | O33: =M33-N33 -> 770 | P33: =ROUND(O33+L33,0) -> 800 | Q33: 0 | R33: =ROUND(H33*Q33,0) -> 0 | S33: =ROUND(H33*117.65%-R33,0) -> 34,709 | T33: =ROUND(H33*25%,0) -> 7,376 | U33: =+T33 -> 7,376 | V33: 13.08.2026 | W33: =ROUND(H33*92.65%-R33,0) -> 27,334 | X33: 27332 | Y33: 24.08.2026 | Z33: =IF(OR(Y33="",Y33=0),H33*0.0118*CEILING((TODAY()-DATE(2026,8,22))/7,1),IF(DATE(VALUE(RIGHT(Y33,4)),VALUE(MID(Y33,4,2)),VALUE(LEFT(Y33,2)))<=DATE(2026,8,24),0,H33*0.0118*CEILING((DATE(VALUE(RIGHT(Y33,4)),VALUE(MID(Y33,4,2)),VALUE(LEFT(Y33,2)))-DATE(2026,8,22))/7,1))) -> 0 | AC33: =U33+X33+AA33 -> 34,708 | AD33: =S33-AC33 -> 1 | AE33: DR2640100046 | AF33: 1800003313 | AG33: 27.08.2026
A34: 30 | B34: Scrap of Empty oil Barrels | C34: 702 | D34: 21979 | E34: NO | F34: 2062 | G34: STERLING ENTERPRISES | H34: 21060 | I34: =ROUND(H34*18%,0) -> 3,791 | J34: =+H34+I34 -> 24,851 | K34: =ROUND((H34+I34)*2%,0) -> 497 | L34: =H34*0.1% -> 21 | M34: =H34*2.25%*118% -> 559 | N34: =H34*2.25%*2% -> 9 | O34: =M34-N34 -> 550 | P34: =ROUND(O34+L34,0) -> 571 | Q34: 0 | R34: =ROUND(H34*Q34,0) -> 0 | S34: =ROUND(H34*117.65%-R34,0) -> 24,777 | T34: =ROUND(H34*25%,0) -> 5,265 | U34: 5265 | V34: 11.08.2026 | W34: =ROUND(H34*92.65%-R34,0) -> 19,512 | X34: 19512 | Y34: 11.08.2026 | Z34: =IF(OR(Y34="",Y34=0),H34*0.0118*CEILING((TODAY()-DATE(2026,8,22))/7,1),IF(DATE(VALUE(RIGHT(Y34,4)),VALUE(MID(Y34,4,2)),VALUE(LEFT(Y34,2)))<=DATE(2026,8,24),0,H34*0.0118*CEILING((DATE(VALUE(RIGHT(Y34,4)),VALUE(MID(Y34,4,2)),VALUE(LEFT(Y34,2)))-DATE(2026,8,22))/7,1))) -> 0 | AC34: =U34+X34+AA34 -> 24,777 | AD34: =S34-AC34 -> 0 | AE34: DR2640100022 | AF34: 1800003161 | AG34: 14.08.2026
A35: 150 | B35: Scrap of empty oil drums | C35: 571 | D35: 21980 | E35: NO | F35: 2067 | G35: WATAN SCRAP TRADERS | H35: 85650 | I35: =ROUND(H35*18%,0) -> 15,417 | J35: =+H35+I35 -> 101,067 | K35: =ROUND((H35+I35)*2%,0) -> 2,021 | L35: =H35*0.1% -> 86 | M35: =H35*2.25%*118% -> 2,274 | N35: =H35*2.25%*2% -> 39 | O35: =M35-N35 -> 2,235 | P35: =ROUND(O35+L35,0) -> 2,321 | Q35: 0 | R35: =ROUND(H35*Q35,0) -> 0 | S35: =ROUND(H35*117.65%-R35,0) -> 100,767 | T35: =ROUND(H35*25%,0) -> 21,413 | U35: 21413 | V35: 14.08.2026 | W35: =ROUND(H35*92.65%-R35,0) -> 79,355 | X35: 79354 | Y35: 20.08.2026 | Z35: =IF(OR(Y35="",Y35=0),H35*0.0118*CEILING((TODAY()-DATE(2026,8,22))/7,1),IF(DATE(VALUE(RIGHT(Y35,4)),VALUE(MID(Y35,4,2)),VALUE(LEFT(Y35,2)))<=DATE(2026,8,24),0,H35*0.0118*CEILING((DATE(VALUE(RIGHT(Y35,4)),VALUE(MID(Y35,4,2)),VALUE(LEFT(Y35,2)))-DATE(2026,8,22))/7,1))) -> 0 | AC35: =U35+X35+AA35 -> 100,767 | AD35: =S35-AC35 -> 0 | AE35: DR2640100027 | AF35: 1800003248 | AG35: 20.08.2026
A36: 1 | B36: Scrap of 33 KV CB | C36: 54000 | D36: 21980 | E36: NO | F36: 2069 | G36: STERLING ENTERPRISES | H36: 54000 | I36: =ROUND(H36*18%,0) -> 9,720 | J36: =+H36+I36 -> 63,720 | K36: =ROUND((H36+I36)*2%,0) -> 1,274 | L36: =H36*0.1% -> 54 | M36: =H36*2.25%*118% -> 1,434 | N36: =H36*2.25%*2% -> 24 | O36: =M36-N36 -> 1,409 | P36: =ROUND(O36+L36,0) -> 1,463 | Q36: 0 | R36: =ROUND(H36*Q36,0) -> 0 | S36: =ROUND(H36*117.65%-R36,0) -> 63,531 | T36: =ROUND(H36*25%,0) -> 13,500 | U36: 13500 | V36: 11.08.2026 | W36: =ROUND(H36*92.65%-R36,0) -> 50,031 | Y36: 0 | Z36: =IF(OR(Y36="",Y36=0),H36*0.0118*CEILING((TODAY()-DATE(2026,8,22))/7,1),IF(DATE(VALUE(RIGHT(Y36,4)),VALUE(MID(Y36,4,2)),VALUE(LEFT(Y36,2)))<=DATE(2026,8,24),0,H36*0.0118*CEILING((DATE(VALUE(RIGHT(Y36,4)),VALUE(MID(Y36,4,2)),VALUE(LEFT(Y36,2)))-DATE(2026,8,22))/7,1))) -> 1,912 | AC36: =U36+X36+AA36 -> 13,500 | AD36: =S36-AC36 -> 50,031
A37: 3 | B37: Scrap of 66 KV Isolater | C37: 25001 | D37: 21980 | E37: NO | F37: 2071 | G37: NATIONAL ENTERPRISES | H37: 75003 | I37: =ROUND(H37*18%,0) -> 13,501 | J37: =+H37+I37 -> 88,504 | K37: =ROUND((H37+I37)*2%,0) -> 1,770 | L37: =H37*0.1% -> 75 | M37: =H37*2.25%*118% -> 1,991 | N37: =H37*2.25%*2% -> 34 | O37: =M37-N37 -> 1,958 | P37: =ROUND(O37+L37,0) -> 2,033 | Q37: 0 | R37: =ROUND(H37*Q37,0) -> 0 | S37: =ROUND(H37*117.65%-R37,0) -> 88,241 | T37: =ROUND(H37*25%,0) -> 18,751 | U37: =+T37 -> 18,751 | V37: 13.08.2026 | W37: =ROUND(H37*92.65%-R37,0) -> 69,490 | X37: 69491 | Y37: 24.08.2026 | Z37: =IF(OR(Y37="",Y37=0),H37*0.0118*CEILING((TODAY()-DATE(2026,8,22))/7,1),IF(DATE(VALUE(RIGHT(Y37,4)),VALUE(MID(Y37,4,2)),VALUE(LEFT(Y37,2)))<=DATE(2026,8,24),0,H37*0.0118*CEILING((DATE(VALUE(RIGHT(Y37,4)),VALUE(MID(Y37,4,2)),VALUE(LEFT(Y37,2)))-DATE(2026,8,22))/7,1))) -> 0 | AC37: =U37+X37+AA37 -> 88,242 | AD37: =S37-AC37 -> (1) | AE37: DR2640100040 | AF37: 1800003314 | AG37: 27.08.2026
A38: 3 | B38: Scrap of 132 KV CT | C38: 70001 | D38: 21980 | E38: NO | F38: 2086 | G38: KASHYAP TRADING CO | H38: 210003 | I38: =ROUND(H38*18%,0) -> 37,801 | J38: =+H38+I38 -> 247,804 | K38: =ROUND((H38+I38)*2%,0) -> 4,956 | L38: =H38*0.1% -> 210 | M38: =H38*2.25%*118% -> 5,576 | N38: =H38*2.25%*2% -> 95 | O38: =M38-N38 -> 5,481 | P38: =ROUND(O38+L38,0) -> 5,691 | Q38: 0 | R38: =ROUND(H38*Q38,0) -> 0 | S38: =ROUND(H38*117.65%-R38,0) -> 247,069 | T38: =ROUND(H38*25%,0) -> 52,501 | U38: 52501 | V38: 17.08.2026 | W38: =ROUND(H38*92.65%-R38,0) -> 194,568 | X38: 194568 | Y38: 17.08.2026 | Z38: =IF(OR(Y38="",Y38=0),H38*0.0118*CEILING((TODAY()-DATE(2026,8,22))/7,1),IF(DATE(VALUE(RIGHT(Y38,4)),VALUE(MID(Y38,4,2)),VALUE(LEFT(Y38,2)))<=DATE(2026,8,24),0,H38*0.0118*CEILING((DATE(VALUE(RIGHT(Y38,4)),VALUE(MID(Y38,4,2)),VALUE(LEFT(Y38,2)))-DATE(2026,8,22))/7,1))) -> 0 | AC38: =U38+X38+AA38 -> 247,069 | AD38: =S38-AC38 -> 0 | AE38: DR2640100025 | AF38: 1800003226 | AG38: 19.08.2026
A39: 2 | B39: Scrap of 66 kv TBC C & R Panel | C39: 15006 | D39: 21980 | E39: NO | F39: 2089 | G39: S M ENTERPRISES | H39: 30012 | I39: =ROUND(H39*18%,0) -> 5,402 | J39: =+H39+I39 -> 35,414 | K39: =ROUND((H39+I39)*2%,0) -> 708 | L39: =H39*0.1% -> 30 | M39: =H39*2.25%*118% -> 797 | N39: =H39*2.25%*2% -> 14 | O39: =M39-N39 -> 783 | P39: =ROUND(O39+L39,0) -> 813 | Q39: 0 | R39: =ROUND(H39*Q39,0) -> 0 | S39: =ROUND(H39*117.65%-R39,0) -> 35,309 | T39: =ROUND(H39*25%,0) -> 7,503 | U39: 7503 | V39: 14.08.2026 | W39: =ROUND(H39*92.65%-R39,0) -> 27,806 | X39: 27806 | Y39: 01.09.2026 | Z39: =IF(OR(Y39="",Y39=0),H39*0.0118*CEILING((TODAY()-DATE(2026,8,22))/7,1),IF(DATE(VALUE(RIGHT(Y39,4)),VALUE(MID(Y39,4,2)),VALUE(LEFT(Y39,2)))<=DATE(2026,8,24),0,H39*0.0118*CEILING((DATE(VALUE(RIGHT(Y39,4)),VALUE(MID(Y39,4,2)),VALUE(LEFT(Y39,2)))-DATE(2026,8,22))/7,1))) -> 708 | AA39: 708 | AB39: 01.09.2026 | AC39: =U39+X39+AA39 -> 36,017 | AD39: =S39-AC39 -> (708)
A40: 3 | B40: Scrap of 132 KV CT | C40: 40003 | D40: 21980 | E40: NO | F40: 2091 | G40: S M ENTERPRISES | H40: 120009 | I40: =ROUND(H40*18%,0) -> 21,602 | J40: =+H40+I40 -> 141,611 | K40: =ROUND((H40+I40)*2%,0) -> 2,832 | L40: =H40*0.1% -> 120 | M40: =H40*2.25%*118% -> 3,186 | N40: =H40*2.25%*2% -> 54 | O40: =M40-N40 -> 3,132 | P40: =ROUND(O40+L40,0) -> 3,252 | Q40: 0 | R40: =ROUND(H40*Q40,0) -> 0 | S40: =ROUND(H40*117.65%-R40,0) -> 141,191 | T40: =ROUND(H40*25%,0) -> 30,002 | U40: 30002 | V40: 14.08.2026 | W40: =ROUND(H40*92.65%-R40,0) -> 111,188 | X40: 111189 | Y40: 01.09.2026 | Z40: =IF(OR(Y40="",Y40=0),H40*0.0118*CEILING((TODAY()-DATE(2026,8,22))/7,1),IF(DATE(VALUE(RIGHT(Y40,4)),VALUE(MID(Y40,4,2)),VALUE(LEFT(Y40,2)))<=DATE(2026,8,24),0,H40*0.0118*CEILING((DATE(VALUE(RIGHT(Y40,4)),VALUE(MID(Y40,4,2)),VALUE(LEFT(Y40,2)))-DATE(2026,8,22))/7,1))) -> 2,832 | AA40: 2832 | AB40: 01.09.2026 | AC40: =U40+X40+AA40 -> 144,023 | AD40: =S40-AC40 -> (2,832)
H41: =SUM(H4:H40) -> 15,130,598 | I41: =SUM(I4:I40) -> 2,723,508 | J41: =SUM(J4:J40) -> 17,854,106 | K41: =SUM(K4:K40) -> 357,082 | L41: =SUM(L4:L40) -> 15,131 | M41: =SUM(M4:M40) -> 401,717 | N41: =SUM(N4:N40) -> 6,809 | O41: =SUM(O4:O40) -> 394,909 | P41: =SUM(P4:P40) -> 410,039 | R41: =SUM(R4:R40) -> 83,029 | S41: =SUM(S4:S40) -> 17,718,123 | T41: =SUM(T4:T40) -> 3,782,654 | U41: =SUM(U4:U40) -> 3,782,654 | W41: =SUM(W4:W40) -> 13,935,473 | X41: =SUM(X4:X40) -> 13,137,293 | Z41: =SUM(Z4:Z40) -> 34,459 | AA41: =SUM(AA4:AA40) -> 3,540 | AC41: =SUM(AC4:AC40) -> 16,923,487 | AD41: =SUM(AD4:AD40) -> 794,636
...

Sheet Live Search
A1: MSTC LIMITED • LIVE SEARCH (results grouped by the value you typed, each group totalled, TOTAL MATCHED beneath them, the misses greyed in a REMAINING block, a GRAND TOTAL of both at the foot)
A2: HOW TO USE ▶ click the yellow box B3 and type - a lot number (1874), part of one (187), a buyer (NATIONAL), part of a buyer name, a lot name (COPPER). • WILDCARD / MATCH ANY - separate values with a comma or a slash: 1874, 1923, OMKAR or 1874 / 1923 - and every lot containing ANY of them lights up. • COLUMN SEARCHES - type above any column header in row 4; comma or slash means ANY value in that column, * matches any text and ? matches one character. Filters entered in different columns are combined as ALL. • FACETED / FILTERED - separate them with + or &: NATIONAL + COPPER - and a lot lights up only if it matches EVERY facet. • the two mix: OMKAR, STERLING + COPPER = (OMKAR or STERLING) and COPPER. Up to 8 values, empty ones ignored, spaces around a separator are fine. • THE RESULT IS GROUPED BY THE VALUE YOU TYPED: every value gets its own block of lots with a shaded ∑ total row beneath it, then a blue TOTAL MATCHED row adds every group up at once - the grand total of the rows your search actually hit, sitting right beneath them. Under that a greyed REMAINING block holds the lots that did not match, with its own total, and the green GRAND TOTAL of both sits at the foot. A lot matching two values is counted under the first one only, so TOTAL MATCHED + REMAINING always equals GRAND TOTAL, and with nothing typed the matched row is the whole list. • clear the box and all 37 come back in one ALL LOTS block. • cell F3 narrows what the text is looked for in (lot no. + buyer + name by default). • matching is contains, not case sensitive. • nothing here is typed in: every figure is a live link to Final Calculation Sheet. • columns AK..CU are hidden helpers.
A3: 🔍 SEARCH ▸ | B3: 2015 | E3: SEARCH IN ▸ | F3: Lot No. + Buyer + Name | G3: MATCHES ▸ | H3: =SUM($AM$5:$AM$41)&" of 37" -> 1 of 37 | I3: =IF(AND($B$3="",COUNTIF($A$4:$AI$4,"<>")=0),"◀ type in the yellow box B3 or a yellow cell above any header - a lot no., a buyer, a lot name... several values: comma or / = ANY of them, + or & = ALL of them","matching "&SUM($AM$5:$AM$41)&" of 37 lots • search: "&IF($B$3="","(column fields)",$B$3)&" • in: "&$F$3&" • column fields are AND filters; grouped by the value typed, the misses greyed in REMAINING, TOTAL MATCHED totals the hits") -> matching 1 of 37 lots • search: 2015 • in: Lot No. + Buyer + Name • column fields are AND filters; grouped by the value typed, the misses greyed in REMAINING, TOTAL MATCHED totals the hits | AK3: the text this lot is searched in | AM3: 1 = this lot matches the search box | AO3: the 'search in' list | AQ3: the box with & -> + and / -> , | AR3: term 1 - rows 4..9: text left, delimiter pos, the term, delimiter, running facet, facet no.
AO4: Lot No. + Buyer + Name | AQ4: =SUBSTITUTE(SUBSTITUTE($B$3,"&","+"),"/",",") -> 2015 | AR4: =$AQ$4 -> 2015 | AS4: =IF(OR($AR$4="",$AR$5=99999),"",MID($AR$4,$AR$5+1,99999)) | AT4: =IF(OR($AS$4="",$AS$5=99999),"",MID($AS$4,$AS$5+1,99999)) | AU4: =IF(OR($AT$4="",$AT$5=99999),"",MID($AT$4,$AT$5+1,99999)) | AV4: =IF(OR($AU$4="",$AU$5=99999),"",MID($AU$4,$AU$5+1,99999)) | AW4: =IF(OR($AV$4="",$AV$5=99999),"",MID($AV$4,$AV$5+1,99999)) | AX4: =IF(OR($AW$4="",$AW$5=99999),"",MID($AW$4,$AW$5+1,99999)) | AY4: =IF(OR($AX$4="",$AX$5=99999),"",MID($AX$4,$AX$5+1,99999)) | BD4: =COUNTIF($AZ$5:$AZ$41,1) -> 1 | BE4: 5 | BF4: =IF($BD4=0,0,$BE4+$BD4) -> 6 | BG4: =IF($BD12=0,$BE12,$BF12+1) -> 7
A5: # | B5: Lot No. | C5: Buyer | D5: Lot Name | E5: Bid Sheet | F5: Quantity | G5: Unit | H5: Rate | I5: Mat. Value | J5: GST | K5: Mat. Value + GST | L5: TCS | M5: TDS u/s 194(O) | N5: Service Charge to MSTC | O5: TDS u/s 194(H) | P5: Net Service Charge (post TDS 194H) | Q5: Service charge to MSTC | R5: GST TDS Rate | S5: GST TDS | T5: Total Receivables in Cash | U5: Security Deposit (Expected) | V5: Security Deposit (Received) | W5: Date of Receipt (col V) | X5: Final Payment (Expected) | Y5: Final Payment (Received) | Z5: Date of Receipt (col Y) | AA5: LPP Expected | AB5: LPP Received | AC5: Date of Recepit of LPP | AD5: Total Received | AE5: Outstanding | AF5: Invoice No. | AG5: SAP Document | AH5: Doc./Invoice Date | AI5: Payment Status | AK5: =IF($F$3="Lot No.",'Final Calculation Sheet'!$F$4,IF($F$3="Buyer",'Final Calculation Sheet'!$G$4,IF($F$3="Lot Name",'Final Calculation Sheet'!$B$4,IF($F$3="Bid Sheet",'Final Calculation Sheet'!$D$4,IF($F$3="Unit",'Final Calculation Sheet'!$E$4,'Final Calculation Sheet'!$F$4&" "&'Final Calculation Sheet'!$G$4&" "&'Final Calculation Sheet'!$B$4))))) -> 1763 AL HAMD TRADE CORPORATION Lot No. | AM5: =IF(COUNTIF($BM5:$CU5,0)>0,0,IF($B$3="",1,IF(AND(IF(COUNTIF($AR$9:$AY$9,1)=0,TRUE,SUMPRODUCT(($AR$9:$AY$9=1)*($AR$6:$AY$6<>"")*ISNUMBER(SEARCH($AR$6:$AY$6,$AK5)))>0),IF(COUNTIF($AR$9:$AY$9,2)=0,TRUE,SUMPRODUCT(($AR$9:$AY$9=2)*($AR$6:$AY$6<>"")*ISNUMBER(SEARCH($AR$6:$AY$6,$AK5)))>0),IF(COUNTIF($AR$9:$AY$9,3)=0,TRUE,SUMPRODUCT(($AR$9:$AY$9=3)*($AR$6:$AY$6<>"")*ISNUMBER(SEARCH($AR$6:$AY$6,$AK5)))>0),IF(COUNTIF($AR$9:$AY$9,4)=0,TRUE,SUMPRODUCT(($AR$9:$AY$9=4)*($AR$6:$AY$6<>"")*ISNUMBER(SEARCH($AR$6:$AY$6,$AK5)))>0),IF(COUNTIF($AR$9:$AY$9,5)=0,TRUE,SUMPRODUCT(($AR$9:$AY$9=5)*($AR$6:$AY$6<>"")*ISNUMBER(SEARCH($AR$6:$AY$6,$AK5)))>0),IF(COUNTIF($AR$9:$AY$9,6)=0,TRUE,SUMPRODUCT(($AR$9:$AY$9=6)*($AR$6:$AY$6<>"")*ISNUMBER(SEARCH($AR$6:$AY$6,$AK5)))>0),IF(COUNTIF($AR$9:$AY$9,7)=0,TRUE,SUMPRODUCT(($AR$9:$AY$9=7)*($AR$6:$AY$6<>"")*ISNUMBER(SEARCH($AR$6:$AY$6,$AK5)))>0),IF(COUNTIF($AR$9:$AY$9,8)=0,TRUE,SUMPRODUCT(($AR$9:$AY$9=8)*($AR$6:$AY$6<>"")*ISNUMBER(SEARCH($AR$6:$AY$6,$AK5)))>0)),1,0))) -> 0 | AO5: Lot No. | AR5: =IF($AR$4="",99999,MIN(IFERROR(FIND(",",$AR$4),99999),IFERROR(FIND("+",$AR$4),99999))) -> 99999 | AS5: =IF($AS$4="",99999,MIN(IFERROR(FIND(",",$AS$4),99999),IFERROR(FIND("+",$AS$4),99999))) -> 99999 | AT5: =IF($AT$4="",99999,MIN(IFERROR(FIND(",",$AT$4),99999),IFERROR(FIND("+",$AT$4),99999))) -> 99999 | AU5: =IF($AU$4="",99999,MIN(IFERROR(FIND(",",$AU$4),99999),IFERROR(FIND("+",$AU$4),99999))) -> 99999 | AV5: =IF($AV$4="",99999,MIN(IFERROR(FIND(",",$AV$4),99999),IFERROR(FIND("+",$AV$4),99999))) -> 99999 | AW5: =IF($AW$4="",99999,MIN(IFERROR(FIND(",",$AW$4),99999),IFERROR(FIND("+",$AW$4),99999))) -> 99999 | AX5: =IF($AX$4="",99999,MIN(IFERROR(FIND(",",$AX$4),99999),IFERROR(FIND("+",$AX$4),99999))) -> 99999 | AY5: =IF($AY$4="",99999,MIN(IFERROR(FIND(",",$AY$4),99999),IFERROR(FIND("+",$AY$4),99999))) -> 99999 | AZ5: =IF($B$3="",IF(COUNTIF($A$4:$AI$4,"<>")=0,9,IF($AM5=1,9,10)),IF($AM5=0,10,IF(AND($AR$6<>"",ISNUMBER(SEARCH($AR$6,$AK5))),1,IF(AND($AS$6<>"",ISNUMBER(SEARCH($AS$6,$AK5))),2,IF(AND($AT$6<>"",ISNUMBER(SEARCH($AT$6,$AK5))),3,IF(AND($AU$6<>"",ISNUMBER(SEARCH($AU$6,$AK5))),4,IF(AND($AV$6<>"",ISNUMBER(SEARCH($AV$6,$AK5))),5,IF(AND($AW$6<>"",ISNUMBER(SEARCH($AW$6,$AK5))),6,IF(AND($AX$6<>"",ISNUMBER(SEARCH($AX$6,$AK5))),7,IF(AND($AY$6<>"",ISNUMBER(SEARCH($AY$6,$AK5))),8,0)))))))))) -> 10 | BA5: =SUMPRODUCT(($AZ$5:$AZ$41=$AZ5)*($BC$5:$BC$41<$BC5))+1 -> 1 | BB5: =IF(INDEX($BF$4:$BF$13,$AZ5)=0,0,INDEX($BE$4:$BE$13,$AZ5)+$BA5-1) -> 8 | BC5: 4 | BD5: =COUNTIF($AZ$5:$AZ$41,2) -> 0 | BE5: =IF($BD4=0,$BE4,$BF4+1) -> 7 | BF5: =IF($BD5=0,0,$BE5+$BD5) -> 0 | BG5: =IF($BD13=0,$BE13,$BF13+1) -> 45 | BH5: =IFERROR(MATCH(5,$BF$4:$BF$13,0),0) -> 0 | BI5: =IF(5=$BG$5,1,0) -> 0 | BJ5: {=IF(OR($BH5>0,$BI5=1,$BL5=1),0,IFERROR(INDEX($BC$5:$BC$41,MATCH(5,$BB$5:$BB$41,0)),0))} -> 17 | BK5: {=IF($BJ5>0,IF(INDEX($AZ$5:$AZ$41,MATCH(5,$BB$5:$BB$41,0))=10,1,0),IF($BH5=10,1,0))} -> 0 | BL5: =IF(5=$BG$4,1,0) -> 0 | BM5: =IF($A$4="",1,--(SUMPRODUCT(--(TRIM(MID(SUBSTITUTE(SUBSTITUTE($A$4,"/",","),",",REPT(" ",99)),(ROW($1:$8)-1)*99+1,99))<>""),--ISNUMBER(SEARCH(TRIM(MID(SUBSTITUTE(SUBSTITUTE($A$4,"/",","),",",REPT(" ",99)),(ROW($1:$8)-1)*99+1,99)),IFERROR((ROW()-4)&"",""))))>0)) -> 1 | BN5: =IF($B$4="",1,--(SUMPRODUCT(--(TRIM(MID(SUBSTITUTE(SUBSTITUTE($B$4,"/",","),",",REPT(" ",99)),(ROW($1:$8)-1)*99+1,99))<>""),--ISNUMBER(SEARCH(TRIM(MID(SUBSTITUTE(SUBSTITUTE($B$4,"/",","),",",REPT(" ",99)),(ROW($1:$8)-1)*99+1,99)),IFERROR(('Final Calculation Sheet'!$F$4)&"",""))))>0)) -> 1 | BO5: =IF($C$4="",1,--(SUMPRODUCT(--(TRIM(MID(SUBSTITUTE(SUBSTITUTE($C$4,"/",","),",",REPT(" ",99)),(ROW($1:$8)-1)*99+1,99))<>""),--ISNUMBER(SEARCH(TRIM(MID(SUBSTITUTE(SUBSTITUTE($C$4,"/",","),",",REPT(" ",99)),(ROW($1:$8)-1)*99+1,99)),IFERROR(('Final Calculation Sheet'!$G$4)&"",""))))>0)) -> 1 | BP5: =IF($D$4="",1,--(SUMPRODUCT(--(TRIM(MID(SUBSTITUTE(SUBSTITUTE($D$4,"/",","),",",REPT(" ",99)),(ROW($1:$8)-1)*99+1,99))<>""),--ISNUMBER(SEARCH(TRIM(MID(SUBSTITUTE(SUBSTITUTE($D$4,"/",","),",",REPT(" ",99)),(ROW($1:$8)-1)*99+1,99)),IFERROR(('Final Calculation Sheet'!$B$4)&"",""))))>0)) -> 1 | BQ5: =IF($E$4="",1,--(SUMPRODUCT(--(TRIM(MID(SUBSTITUTE(SUBSTITUTE($E$4,"/",","),",",REPT(" ",99)),(ROW($1:$8)-1)*99+1,99))<>""),--ISNUMBER(SEARCH(TRIM(MID(SUBSTITUTE(SUBSTITUTE($E$4,"/",","),",",REPT(" ",99)),(ROW($1:$8)-1)*99+1,99)),IFERROR(('Final Calculation Sheet'!$D$4)&"",""))))>0)) -> 1 | BR5: =IF($F$4="",1,--(SUMPRODUCT(--(TRIM(MID(SUBSTITUTE(SUBSTITUTE($F$4,"/",","),",",REPT(" ",99)),(ROW($1:$8)-1)*99+1,99))<>""),--ISNUMBER(SEARCH(TRIM(MID(SUBSTITUTE(SUBSTITUTE($F$4,"/",","),",",REPT(" ",99)),(ROW($1:$8)-1)*99+1,99)),IFERROR(('Final Calculation Sheet'!$A$4)&"",""))))>0)) -> 1 | BS5: =IF($G$4="",1,--(SUMPRODUCT(--(TRIM(MID(SUBSTITUTE(SUBSTITUTE($G$4,"/",","),",",REPT(" ",99)),(ROW($1:$8)-1)*99+1,99))<>""),--ISNUMBER(SEARCH(TRIM(MID(SUBSTITUTE(SUBSTITUTE($G$4,"/",","),",",REPT(" ",99)),(ROW($1:$8)-1)*99+1,99)),IFERROR(('Final Calculation Sheet'!$E$4)&"",""))))>0)) -> 1 | BT5: =IF($H$4="",1,--(SUMPRODUCT(--(TRIM(MID(SUBSTITUTE(SUBSTITUTE($H$4,"/",","),",",REPT(" ",99)),(ROW($1:$8)-1)*99+1,99))<>""),--ISNUMBER(SEARCH(TRIM(MID(SUBSTITUTE(SUBSTITUTE($H$4,"/",","),",",REPT(" ",99)),(ROW($1:$8)-1)*99+1,99)),IFERROR(('Final Calculation Sheet'!$C$4)&"",""))))>0)) -> 1 | BU5: =IF($I$4="",1,--(SUMPRODUCT(--(TRIM(MID(SUBSTITUTE(SUBSTITUTE($I$4,"/",","),",",REPT(" ",99)),(ROW($1:$8)-1)*99+1,99))<>""),--ISNUMBER(SEARCH(TRIM(MID(SUBSTITUTE(SUBSTITUTE($I$4,"/",","),",",REPT(" ",99)),(ROW($1:$8)-1)*99+1,99)),IFERROR(('Final Calculation Sheet'!$H$4)&"",""))))>0)) -> 1 | BV5: =IF($J$4="",1,--(SUMPRODUCT(--(TRIM(MID(SUBSTITUTE(SUBSTITUTE($J$4,"/",","),",",REPT(" ",99)),(ROW($1:$8)-1)*99+1,99))<>""),--ISNUMBER(SEARCH(TRIM(MID(SUBSTITUTE(SUBSTITUTE($J$4,"/",","),",",REPT(" ",99)),(ROW($1:$8)-1)*99+1,99)),IFERROR(('Final Calculation Sheet'!$I$4)&"",""))))>0)) -> 1 | BW5: =IF($K$4="",1,--(SUMPRODUCT(--(TRIM(MID(SUBSTITUTE(SUBSTITUTE($K$4,"/",","),",",REPT(" ",99)),(ROW($1:$8)-1)*99+1,99))<>""),--ISNUMBER(SEARCH(TRIM(MID(SUBSTITUTE(SUBSTITUTE($K$4,"/",","),",",REPT(" ",99)),(ROW($1:$8)-1)*99+1,99)),IFERROR(('Final Calculation Sheet'!$J$4)&"",""))))>0)) -> 1 | BX5: =IF($L$4="",1,--(SUMPRODUCT(--(TRIM(MID(SUBSTITUTE(SUBSTITUTE($L$4,"/",","),",",REPT(" ",99)),(ROW($1:$8)-1)*99+1,99))<>""),--ISNUMBER(SEARCH(TRIM(MID(SUBSTITUTE(SUBSTITUTE($L$4,"/",","),",",REPT(" ",99)),(ROW($1:$8)-1)*99+1,99)),IFERROR(('Final Calculation Sheet'!$K$4)&"",""))))>0)) -> 1 | BY5: =IF($M$4="",1,--(SUMPRODUCT(--(TRIM(MID(SUBSTITUTE(SUBSTITUTE($M$4,"/",","),",",REPT(" ",99)),(ROW($1:$8)-1)*99+1,99))<>""),--ISNUMBER(SEARCH(TRIM(MID(SUBSTITUTE(SUBSTITUTE($M$4,"/",","),",",REPT(" ",99)),(ROW($1:$8)-1)*99+1,99)),IFERROR(('Final Calculation Sheet'!$L$4)&"",""))))>0)) -> 1 | BZ5: =IF($N$4="",1,--(SUMPRODUCT(--(TRIM(MID(SUBSTITUTE(SUBSTITUTE($N$4,"/",","),",",REPT(" ",99)),(ROW($1:$8)-1)*99+1,99))<>""),--ISNUMBER(SEARCH(TRIM(MID(SUBSTITUTE(SUBSTITUTE($N$4,"/",","),",",REPT(" ",99)),(ROW($1:$8)-1)*99+1,99)),IFERROR(('Final Calculation Sheet'!$M$4)&"",""))))>0)) -> 1 | CA5: =IF($O$4="",1,--(SUMPRODUCT(--(TRIM(MID(SUBSTITUTE(SUBSTITUTE($O$4,"/",","),",",REPT(" ",99)),(ROW($1:$8)-1)*99+1,99))<>""),--ISNUMBER(SEARCH(TRIM(MID(SUBSTITUTE(SUBSTITUTE($O$4,"/",","),",",REPT(" ",99)),(ROW($1:$8)-1)*99+1,99)),IFERROR(('Final Calculation Sheet'!$N$4)&"",""))))>0)) -> 1 | CB5: =IF($P$4="",1,--(SUMPRODUCT(--(TRIM(MID(SUBSTITUTE(SUBSTITUTE($P$4,"/",","),",",REPT(" ",99)),(ROW($1:$8)-1)*99+1,99))<>""),--ISNUMBER(SEARCH(TRIM(MID(SUBSTITUTE(SUBSTITUTE($P$4,"/",","),",",REPT(" ",99)),(ROW($1:$8)-1)*99+1,99)),IFERROR(('Final Calculation Sheet'!$O$4)&"",""))))>0)) -> 1 | CC5: =IF($Q$4="",1,--(SUMPRODUCT(--(TRIM(MID(SUBSTITUTE(SUBSTITUTE($Q$4,"/",","),",",REPT(" ",99)),(ROW($1:$8)-1)*99+1,99))<>""),--ISNUMBER(SEARCH(TRIM(MID(SUBSTITUTE(SUBSTITUTE($Q$4,"/",","),",",REPT(" ",99)),(ROW($1:$8)-1)*99+1,99)),IFERROR(('Final Calculation Sheet'!$P$4)&"",""))))>0)) -> 1 | CD5: =IF($R$4="",1,--(SUMPRODUCT(--(TRIM(MID(SUBSTITUTE(SUBSTITUTE($R$4,"/",","),",",REPT(" ",99)),(ROW($1:$8)-1)*99+1,99))<>""),--ISNUMBER(SEARCH(TRIM(MID(SUBSTITUTE(SUBSTITUTE($R$4,"/",","),",",REPT(" ",99)),(ROW($1:$8)-1)*99+1,99)),IFERROR(('Final Calculation Sheet'!$Q$4)&"",""))))>0)) -> 1 | CE5: =IF($S$4="",1,--(SUMPRODUCT(--(TRIM(MID(SUBSTITUTE(SUBSTITUTE($S$4,"/",","),",",REPT(" ",99)),(ROW($1:$8)-1)*99+1,99))<>""),--ISNUMBER(SEARCH(TRIM(MID(SUBSTITUTE(SUBSTITUTE($S$4,"/",","),",",REPT(" ",99)),(ROW($1:$8)-1)*99+1,99)),IFERROR(('Final Calculation Sheet'!$R$4)&"",""))))>0)) -> 1 | CF5: =IF($T$4="",1,--(SUMPRODUCT(--(TRIM(MID(SUBSTITUTE(SUBSTITUTE($T$4,"/",","),",",REPT(" ",99)),(ROW($1:$8)-1)*99+1,99))<>""),--ISNUMBER(SEARCH(TRIM(MID(SUBSTITUTE(SUBSTITUTE($T$4,"/",","),",",REPT(" ",99)),(ROW($1:$8)-1)*99+1,99)),IFERROR(('Final Calculation Sheet'!$S$4)&"",""))))>0)) -> 1 | CG5: =IF($U$4="",1,--(SUMPRODUCT(--(TRIM(MID(SUBSTITUTE(SUBSTITUTE($U$4,"/",","),",",REPT(" ",99)),(ROW($1:$8)-1)*99+1,99))<>""),--ISNUMBER(SEARCH(TRIM(MID(SUBSTITUTE(SUBSTITUTE($U$4,"/",","),",",REPT(" ",99)),(ROW($1:$8)-1)*99+1,99)),IFERROR(('Final Calculation Sheet'!$T$4)&"",""))))>0)) -> 1 | CH5: =IF($V$4="",1,--(SUMPRODUCT(--(TRIM(MID(SUBSTITUTE(SUBSTITUTE($V$4,"/",","),",",REPT(" ",99)),(ROW($1:$8)-1)*99+1,99))<>""),--ISNUMBER(SEARCH(TRIM(MID(SUBSTITUTE(SUBSTITUTE($V$4,"/",","),",",REPT(" ",99)),(ROW($1:$8)-1)*99+1,99)),IFERROR(('Final Calculation Sheet'!$U$4)&"",""))))>0)) -> 1 | CI5: =IF($W$4="",1,--(SUMPRODUCT(--(TRIM(MID(SUBSTITUTE(SUBSTITUTE($W$4,"/",","),",",REPT(" ",99)),(ROW($1:$8)-1)*99+1,99))<>""),--ISNUMBER(SEARCH(TRIM(MID(SUBSTITUTE(SUBSTITUTE($W$4,"/",","),",",REPT(" ",99)),(ROW($1:$8)-1)*99+1,99)),IFERROR(('Final Calculation Sheet'!$V$4)&"",""))))>0)) -> 1 | CJ5: =IF($X$4="",1,--(SUMPRODUCT(--(TRIM(MID(SUBSTITUTE(SUBSTITUTE($X$4,"/",","),",",REPT(" ",99)),(ROW($1:$8)-1)*99+1,99))<>""),--ISNUMBER(SEARCH(TRIM(MID(SUBSTITUTE(SUBSTITUTE($X$4,"/",","),",",REPT(" ",99)),(ROW($1:$8)-1)*99+1,99)),IFERROR(('Final Calculation Sheet'!$W$4)&"",""))))>0)) -> 1 | CK5: =IF($Y$4="",1,--(SUMPRODUCT(--(TRIM(MID(SUBSTITUTE(SUBSTITUTE($Y$4,"/",","),",",REPT(" ",99)),(ROW($1:$8)-1)*99+1,99))<>""),--ISNUMBER(SEARCH(TRIM(MID(SUBSTITUTE(SUBSTITUTE($Y$4,"/",","),",",REPT(" ",99)),(ROW($1:$8)-1)*99+1,99)),IFERROR(('Final Calculation Sheet'!$X$4)&"",""))))>0)) -> 1 | CL5: =IF($Z$4="",1,--(SUMPRODUCT(--(TRIM(MID(SUBSTITUTE(SUBSTITUTE($Z$4,"/",","),",",REPT(" ",99)),(ROW($1:$8)-1)*99+1,99))<>""),--ISNUMBER(SEARCH(TRIM(MID(SUBSTITUTE(SUBSTITUTE($Z$4,"/",","),",",REPT(" ",99)),(ROW($1:$8)-1)*99+1,99)),IFERROR(('Final Calculation Sheet'!$Y$4)&"",""))))>0)) -> 1 | CM5: =IF($AA$4="",1,--(SUMPRODUCT(--(TRIM(MID(SUBSTITUTE(SUBSTITUTE($AA$4,"/",","),",",REPT(" ",99)),(ROW($1:$8)-1)*99+1,99))<>""),--ISNUMBER(SEARCH(TRIM(MID(SUBSTITUTE(SUBSTITUTE($AA$4,"/",","),",",REPT(" ",99)),(ROW($1:$8)-1)*99+1,99)),IFERROR(('Final Calculation Sheet'!$Z$4)&"",""))))>0)) -> 1 | CN5: =IF($AB$4="",1,--(SUMPRODUCT(--(TRIM(MID(SUBSTITUTE(SUBSTITUTE($AB$4,"/",","),",",REPT(" ",99)),(ROW($1:$8)-1)*99+1,99))<>""),--ISNUMBER(SEARCH(TRIM(MID(SUBSTITUTE(SUBSTITUTE($AB$4,"/",","),",",REPT(" ",99)),(ROW($1:$8)-1)*99+1,99)),IFERROR(('Final Calculation Sheet'!$AA$4)&"",""))))>0)) -> 1 | CO5: =IF($AC$4="",1,--(SUMPRODUCT(--(TRIM(MID(SUBSTITUTE(SUBSTITUTE($AC$4,"/",","),",",REPT(" ",99)),(ROW($1:$8)-1)*99+1,99))<>""),--ISNUMBER(SEARCH(TRIM(MID(SUBSTITUTE(SUBSTITUTE($AC$4,"/",","),",",REPT(" ",99)),(ROW($1:$8)-1)*99+1,99)),IFERROR(('Final Calculation Sheet'!$AB$4)&"",""))))>0)) -> 1 | CP5: =IF($AD$4="",1,--(SUMPRODUCT(--(TRIM(MID(SUBSTITUTE(SUBSTITUTE($AD$4,"/",","),",",REPT(" ",99)),(ROW($1:$8)-1)*99+1,99))<>""),--ISNUMBER(SEARCH(TRIM(MID(SUBSTITUTE(SUBSTITUTE($AD$4,"/",","),",",REPT(" ",99)),(ROW($1:$8)-1)*99+1,99)),IFERROR(('Final Calculation Sheet'!$AC$4)&"",""))))>0)) -> 1 | CQ5: =IF($AE$4="",1,--(SUMPRODUCT(--(TRIM(MID(SUBSTITUTE(SUBSTITUTE($AE$4,"/",","),",",REPT(" ",99)),(ROW($1:$8)-1)*99+1,99))<>""),--ISNUMBER(SEARCH(TRIM(MID(SUBSTITUTE(SUBSTITUTE($AE$4,"/",","),",",REPT(" ",99)),(ROW($1:$8)-1)*99+1,99)),IFERROR(('Final Calculation Sheet'!$AD$4)&"",""))))>0)) -> 1 | CR5: =IF($AF$4="",1,--(SUMPRODUCT(--(TRIM(MID(SUBSTITUTE(SUBSTITUTE($AF$4,"/",","),",",REPT(" ",99)),(ROW($1:$8)-1)*99+1,99))<>""),--ISNUMBER(SEARCH(TRIM(MID(SUBSTITUTE(SUBSTITUTE($AF$4,"/",","),",",REPT(" ",99)),(ROW($1:$8)-1)*99+1,99)),IFERROR(('Final Calculation Sheet'!$AE$4)&"",""))))>0)) -> 1 | CS5: =IF($AG$4="",1,--(SUMPRODUCT(--(TRIM(MID(SUBSTITUTE(SUBSTITUTE($AG$4,"/",","),",",REPT(" ",99)),(ROW($1:$8)-1)*99+1,99))<>""),--ISNUMBER(SEARCH(TRIM(MID(SUBSTITUTE(SUBSTITUTE($AG$4,"/",","),",",REPT(" ",99)),(ROW($1:$8)-1)*99+1,99)),IFERROR(('Final Calculation Sheet'!$AF$4)&"",""))))>0)) -> 1 | CT5: =IF($AH$4="",1,--(SUMPRODUCT(--(TRIM(MID(SUBSTITUTE(SUBSTITUTE($AH$4,"/",","),",",REPT(" ",99)),(ROW($1:$8)-1)*99+1,99))<>""),--ISNUMBER(SEARCH(TRIM(MID(SUBSTITUTE(SUBSTITUTE($AH$4,"/",","),",",REPT(" ",99)),(ROW($1:$8)-1)*99+1,99)),IFERROR(('Final Calculation Sheet'!$AG$4)&"",""))))>0)) -> 1 | CU5: =IF($AI$4="",1,--(SUMPRODUCT(--(TRIM(MID(SUBSTITUTE(SUBSTITUTE($AI$4,"/",","),",",REPT(" ",99)),(ROW($1:$8)-1)*99+1,99))<>""),--ISNUMBER(SEARCH(TRIM(MID(SUBSTITUTE(SUBSTITUTE($AI$4,"/",","),",",REPT(" ",99)),(ROW($1:$8)-1)*99+1,99)),IFERROR((IF('Final Calculation Sheet'!$AD$4<=0,"SETTLED","OUTSTANDING"))&"",""))))>0)) -> 1
