Workbook

Sheet Final Calculation Sheet
B1: MSTC LIMITED - COMBINED BID SHEET (Auctions 21977, 21978, 21979, 21980)
A3: Quantity | B3: 1876, 1923, national e | C3: Rate | D3: Bid Sheet | E3: Unit | F3: Lot No. | G3: Buyer | H3: Mat. Value | I3: GST | J3: Mat. Value + GST | K3: TCS | L3: TDS u/s 194(O) | M3: Service Charge to MSTC | N3: TDS u/s 194(H) | O3: Net Service Charge (post TDS 194H) | P3: Service charge to MSTC | Q3: GST TDS Rate | R3: GST TDS | S3: Total Receivables in Cash | T3: Security Deposit (Expected) | U3: Security Deposit (Received) | V3: Date of Receipt | W3: Final Payment (Expected) | X3: Final Payment (Received) | Y3: Date of Receipt | Z3: LPP Expected | AA3: LPP Received | AB3: Date of Recepit of LPP | AC3: Total Received | AD3: Outstanding | AE3: Invoice No. | AF3: SAP Document | AG3: Doc./Invoice Date
A4: 669 | B4: Lot No. | C4: 1181 | D4: 21980 | E4: KG | F4: 1763 | G4: AL HAMD TRADE CORPORATION | H4: 790089 | I4: =ROUND(H4*18%,0) -> 142216 | J4: =+H4+I4 -> 932305 | K4: =ROUND((H4+I4)*2%,0) -> 18646 | L4: =H4*0.1% -> 790.089 | M4: =H4*2.25%*118% -> 20976.863 | N4: =H4*2.25%*2% -> 355.54005 | O4: =M4-N4 -> 20621.323 | P4: =ROUND(O4+L4,0) -> 21411 | Q4: 0.02 | R4: =ROUND(H4*Q4,0) -> 15802 | S4: =ROUND(H4*117.65%-R4,0) -> 913738 | T4: =ROUND(H4*25%,0) -> 197522 | U4: 197522 | V4: 24.08.2026 | W4: =ROUND(H4*92.65%-R4,0) -> 716215 | X4: 716216 | Y4: 18.08.2026 | Z4: =IF(OR(Y4="",Y4=0),H4*0.0118*CEILING((TODAY()-DATE(2026,8,22))/7,1),IF(DATE(VALUE(RIGHT(Y4,4)),VALUE(MID(Y4,4,2)),VALUE(LEFT(Y4,2)))<=DATE(2026,8,24),0,H4*0.0118*CEILING((DATE(VALUE(RIGHT(Y4,4)),VALUE(MID(Y4,4,2)),VALUE(LEFT(Y4,2)))-DATE(2026,8,22))/7,1))) -> 0 | AC4: =U4+X4+AA4 -> 913738 | AD4: =S4-AC4 -> 0 | AE4: DR2640100029 | AF4: 1800003271 | AG4: 24.08.2026
A5: 270 | B5: Scrap of Empty oil drum | C5: 580 | D5: 21977 | E5: NO | F5: 1874 | G5: NATIONAL ENTERPRISES | H5: 156600 | I5: =ROUND(H5*18%,0) -> 28188 | J5: =+H5+I5 -> 184788 | K5: =ROUND((H5+I5)*2%,0) -> 3696 | L5: =H5*0.1% -> 156.6 | M5: =H5*2.25%*118% -> 4157.73 | N5: =H5*2.25%*2% -> 70.47 | O5: =M5-N5 -> 4087.26 | P5: =ROUND(O5+L5,0) -> 4244 | Q5: 0 | R5: =ROUND(H5*Q5,0) -> 0 | S5: =ROUND(H5*117.65%-R5,0) -> 184240 | T5: =ROUND(H5*25%,0) -> 39150 | U5: =+T5 -> 39150 | V5: 13.08.2026 | W5: =ROUND(H5*92.65%-R5,0) -> 145090 | X5: 145090 | Y5: 24.08.2026 | Z5: =IF(OR(Y5="",Y5=0),H5*0.0118*CEILING((TODAY()-DATE(2026,8,22))/7,1),IF(DATE(VALUE(RIGHT(Y5,4)),VALUE(MID(Y5,4,2)),VALUE(LEFT(Y5,2)))<=DATE(2026,8,24),0,H5*0.0118*CEILING((DATE(VALUE(RIGHT(Y5,4)),VALUE(MID(Y5,4,2)),VALUE(LEFT(Y5,2)))-DATE(2026,8,22))/7,1))) -> 0 | AC5: =U5+X5+AA5 -> 184240 | AD5: =S5-AC5 -> 0 | AE5: DR2640100030 | AF5: 1800003302 | AG5: 27.08.2026
A6: 28 | B6: Scrap of Copper of faulty AC compressor | C6: 1456 | D6: 21977 | E6: KG | F6: 1875 | G6: F R KHANS ENTERPRISES | H6: 40768 | I6: =ROUND(H6*18%,0) -> 7338 | J6: =+H6+I6 -> 48106 | K6: =ROUND((H6+I6)*2%,0) -> 962 | L6: =H6*0.1% -> 40.768 | M6: =H6*2.25%*118% -> 1082.3904 | N6: =H6*2.25%*2% -> 18.3456 | O6: =M6-N6 -> 1064.0448 | P6: =ROUND(O6+L6,0) -> 1105 | Q6: 0 | R6: =ROUND(H6*Q6,0) -> 0 | S6: =ROUND(H6*117.65%-R6,0) -> 47964 | T6: =ROUND(H6*25%,0) -> 10192 | U6: 10192 | V6: 11.08.2026 | W6: =ROUND(H6*92.65%-R6,0) -> 37772 | X6: =+W6+R6 -> 37772 | Y6: 20.08.2026 | Z6: =IF(OR(Y6="",Y6=0),H6*0.0118*CEILING((TODAY()-DATE(2026,8,22))/7,1),IF(DATE(VALUE(RIGHT(Y6,4)),VALUE(MID(Y6,4,2)),VALUE(LEFT(Y6,2)))<=DATE(2026,8,24),0,H6*0.0118*CEILING((DATE(VALUE(RIGHT(Y6,4)),VALUE(MID(Y6,4,2)),VALUE(LEFT(Y6,2)))-DATE(2026,8,22))/7,1))) -> 0 | AC6: =U6+X6+AA6 -> 47964 | AD6: =S6-AC6 -> 0 | AE6: DR2640100047 | AF6: 1800003346 | AG6: 27.08.2026
A7: 3000 | B7: Scrap of MS (extracted from equip cage and empty Sf6 gas cylinder) | C7: 66 | D7: 21977 | E7: KG | F7: 1876 | G7: F R KHANS ENTERPRISES | H7: 198000 | I7: =ROUND(H7*18%,0) -> 35640 | J7: =+H7+I7 -> 233640 | K7: =ROUND((H7+I7)*2%,0) -> 4673 | L7: =H7*0.1% -> 198 | M7: =H7*2.25%*118% -> 5256.9 | N7: =H7*2.25%*2% -> 89.1 | O7: =M7-N7 -> 5167.8 | P7: =ROUND(O7+L7,0) -> 5366 | Q7: 0 | R7: =ROUND(H7*Q7,0) -> 0 | S7: =ROUND(H7*117.65%-R7,0) -> 232947 | T7: =ROUND(H7*25%,0) -> 49500 | U7: 49500 | V7: 11.08.2026 | W7: =ROUND(H7*92.65%-R7,0) -> 183447 | X7: =+W7+R7-1 -> 183446 | Y7: 20.08.2026 | Z7: =IF(OR(Y7="",Y7=0),H7*0.0118*CEILING((TODAY()-DATE(2026,8,22))/7,1),IF(DATE(VALUE(RIGHT(Y7,4)),VALUE(MID(Y7,4,2)),VALUE(LEFT(Y7,2)))<=DATE(2026,8,24),0,H7*0.0118*CEILING((DATE(VALUE(RIGHT(Y7,4)),VALUE(MID(Y7,4,2)),VALUE(LEFT(Y7,2)))-DATE(2026,8,22))/7,1))) -> 0 | AC7: =U7+X7+AA7 -> 232946 | AD7: =S7-AC7 -> 1 | AE7: DR2640100048 | AF7: 1800003347 | AG7: 27.08.2026
A8: 7253 | B8: SCRAP ACSR CONDUCTORS (Conductor Pieces) | C8: 227 | D8: 21980 | E8: KG | F8: 1923 | G8: OMKAR STEELS | H8: 1646431 | I8: =ROUND(H8*18%,0) -> 296358 | J8: =+H8+I8 -> 1942789 | K8: =ROUND((H8+I8)*2%,0) -> 38856 | L8: =H8*0.1% -> 1646.431 | M8: =H8*2.25%*118% -> 43712.743 | N8: =H8*2.25%*2% -> 740.89395 | O8: =M8-N8 -> 42971.849 | P8: =ROUND(O8+L8,0) -> 44618 | Q8: 0.02 | R8: =ROUND(H8*Q8,0) -> 32929 | S8: =ROUND(H8*117.65%-R8,0) -> 1904097 | T8: =ROUND(H8*25%,0) -> 411608 | U8: =+T8 -> 411608 | V8: 14.08.2026 | W8: =ROUND(H8*92.65%-R8,0) -> 1492489 | X8: 1492490 | Y8: 24.08.2026 | Z8: =IF(OR(Y8="",Y8=0),H8*0.0118*CEILING((TODAY()-DATE(2026,8,22))/7,1),IF(DATE(VALUE(RIGHT(Y8,4)),VALUE(MID(Y8,4,2)),VALUE(LEFT(Y8,2)))<=DATE(2026,8,24),0,H8*0.0118*CEILING((DATE(VALUE(RIGHT(Y8,4)),VALUE(MID(Y8,4,2)),VALUE(LEFT(Y8,2)))-DATE(2026,8,22))/7,1))) -> 0 | AC8: =U8+X8+AA8 -> 1904098 | AD8: =S8-AC8 -> -1 | AE8: DR2640100045 | AF8: 1800003315 | AG8: 27.08.2026
A9: 1 | B9: Scrap Power Transformer | C9: 2787314 | D9: 21977 | E9: NO | F9: 1976 | G9: SHAR JAHAN TRADERS | H9: 2787314 | I9: =ROUND(H9*18%,0) -> 501717 | J9: =+H9+I9 -> 3289031 | K9: =ROUND((H9+I9)*2%,0) -> 65781 | L9: =H9*0.1% -> 2787.314 | M9: =H9*2.25%*118% -> 74003.187 | N9: =H9*2.25%*2% -> 1254.2913 | O9: =M9-N9 -> 72748.895 | P9: =ROUND(O9+L9,0) -> 75536 | Q9: 0 | R9: =ROUND(H9*Q9,0) -> 0 | S9: =ROUND(H9*117.65%-R9,0) -> 3279275 | T9: =ROUND(H9*25%,0) -> 696829 | U9: =+T9 -> 696829 | V9: 13.08.2026 | W9: =ROUND(H9*92.65%-R9,0) -> 2582446 | X9: 2582447.1 | Y9: 13.08.2026 | Z9: =IF(OR(Y9="",Y9=0),H9*0.0118*CEILING((TODAY()-DATE(2026,8,22))/7,1),IF(DATE(VALUE(RIGHT(Y9,4)),VALUE(MID(Y9,4,2)),VALUE(LEFT(Y9,2)))<=DATE(2026,8,24),0,H9*0.0118*CEILING((DATE(VALUE(RIGHT(Y9,4)),VALUE(MID(Y9,4,2)),VALUE(LEFT(Y9,2)))-DATE(2026,8,22))/7,1))) -> 0 | AC9: =U9+X9+AA9 -> 3279276.1 | AD9: =S9-AC9 -> -1.0942916 | AE9: DR2640100023 | AF9: 1800003194 | AG9: 17.08.2026
A10: 4 | B10: Scrap of 132 KV CT | C10: 51511 | D10: 21977 | E10: NO | F10: 2002 | G10: NATIONAL ENTERPRISES | H10: 206044 | I10: =ROUND(H10*18%,0) -> 37088 | J10: =+H10+I10 -> 243132 | K10: =ROUND((H10+I10)*2%,0) -> 4863 | L10: =H10*0.1% -> 206.044 | M10: =H10*2.25%*118% -> 5470.4682 | N10: =H10*2.25%*2% -> 92.7198 | O10: =M10-N10 -> 5377.7484 | P10: =ROUND(O10+L10,0) -> 5584 | Q10: 0 | R10: =ROUND(H10*Q10,0) -> 0 | S10: =ROUND(H10*117.65%-R10,0) -> 242411 | T10: =ROUND(H10*25%,0) -> 51511 | U10: =+T10 -> 51511 | V10: 13.08.2026 | W10: =ROUND(H10*92.65%-R10,0) -> 190900 | X10: 190900 | Y10: 24.08.2026 | Z10: =IF(OR(Y10="",Y10=0),H10*0.0118*CEILING((TODAY()-DATE(2026,8,22))/7,1),IF(DATE(VALUE(RIGHT(Y10,4)),VALUE(MID(Y10,4,2)),VALUE(LEFT(Y10,2)))<=DATE(2026,8,24),0,H10*0.0118*CEILING((DATE(VALUE(RIGHT(Y10,4)),VALUE(MID(Y10,4,2)),VALUE(LEFT(Y10,2)))-DATE(2026,8,22))/7,1))) -> 0 | AC10: =U10+X10+AA10 -> 242411 | AD10: =S10-AC10 -> 0 | AE10: DR2640100031 | AF10: 1800003303 | AG10: 27.08.2026
A11: 1 | B11: Scrap of 145 KV CB | C11: 65007 | D11: 21977 | E11: NO | F11: 2003 | G11: NATIONAL ENTERPRISES | H11: 65007 | I11: =ROUND(H11*18%,0) -> 11701 | J11: =+H11+I11 -> 76708 | K11: =ROUND((H11+I11)*2%,0) -> 1534 | L11: =H11*0.1% -> 65.007 | M11: =H11*2.25%*118% -> 1725.9358 | N11: =H11*2.25%*2% -> 29.25315 | O11: =M11-N11 -> 1696.6827 | P11: =ROUND(O11+L11,0) -> 1762 | Q11: 0 | R11: =ROUND(H11*Q11,0) -> 0 | S11: =ROUND(H11*117.65%-R11,0) -> 76481 | T11: =ROUND(H11*25%,0) -> 16252 | U11: =+T11 -> 16252 | V11: 13.08.2026 | W11: =ROUND(H11*92.65%-R11,0) -> 60229 | X11: 60229 | Y11: 24.08.2026 | Z11: =IF(OR(Y11="",Y11=0),H11*0.0118*CEILING((TODAY()-DATE(2026,8,22))/7,1),IF(DATE(VALUE(RIGHT(Y11,4)),VALUE(MID(Y11,4,2)),VALUE(LEFT(Y11,2)))<=DATE(2026,8,24),0,H11*0.0118*CEILING((DATE(VALUE(RIGHT(Y11,4)),VALUE(MID(Y11,4,2)),VALUE(LEFT(Y11,2)))-DATE(2026,8,22))/7,1))) -> 0 | AC11: =U11+X11+AA11 -> 76481 | AD11: =S11-AC11 -> 0 | AE11: DR2640100032 | AF11: 1800003304 | AG11: 27.08.2026
A12: 1 | B12: Scrap of 220KV CT | C12: 70006 | D12: 21977 | E12: NO | F12: 2005 | G12: NATIONAL ENTERPRISES | H12: 70006 | I12: =ROUND(H12*18%,0) -> 12601 | J12: =+H12+I12 -> 82607 | K12: =ROUND((H12+I12)*2%,0) -> 1652 | L12: =H12*0.1% -> 70.006 | M12: =H12*2.25%*118% -> 1858.6593 | N12: =H12*2.25%*2% -> 31.5027 | O12: =M12-N12 -> 1827.1566 | P12: =ROUND(O12+L12,0) -> 1897 | Q12: 0 | R12: =ROUND(H12*Q12,0) -> 0 | S12: =ROUND(H12*117.65%-R12,0) -> 82362 | T12: =ROUND(H12*25%,0) -> 17502 | U12: =+T12 -> 17502 | V12: 13.08.2026 | W12: =ROUND(H12*92.65%-R12,0) -> 64861 | X12: 64859 | Y12: 24.08.2026 | Z12: =IF(OR(Y12="",Y12=0),H12*0.0118*CEILING((TODAY()-DATE(2026,8,22))/7,1),IF(DATE(VALUE(RIGHT(Y12,4)),VALUE(MID(Y12,4,2)),VALUE(LEFT(Y12,2)))<=DATE(2026,8,24),0,H12*0.0118*CEILING((DATE(VALUE(RIGHT(Y12,4)),VALUE(MID(Y12,4,2)),VALUE(LEFT(Y12,2)))-DATE(2026,8,22))/7,1))) -> 0 | AC12: =U12+X12+AA12 -> 82361 | AD12: =S12-AC12 -> 1 | AE12: DR2640100033 | AF12: 1800003305 | AG12: 27.08.2026
A13: 25 | B13: Scrap of empty oil drums | C13: 700 | D13: 21977 | E13: NO | F13: 2006 | G13: STERLING ENTERPRISES | H13: 17500 | I13: =ROUND(H13*18%,0) -> 3150 | J13: =+H13+I13 -> 20650 | K13: =ROUND((H13+I13)*2%,0) -> 413 | L13: =H13*0.1% -> 17.5 | M13: =H13*2.25%*118% -> 464.625 | N13: =H13*2.25%*2% -> 7.875 | O13: =M13-N13 -> 456.75 | P13: =ROUND(O13+L13,0) -> 474 | Q13: 0 | R13: =ROUND(H13*Q13,0) -> 0 | S13: =ROUND(H13*117.65%-R13,0) -> 20589 | T13: =ROUND(H13*25%,0) -> 4375 | U13: 4375 | V13: 11.08.2026 | W13: =ROUND(H13*92.65%-R13,0) -> 16214 | X13: 16214 | Y13: 11.08.2026 | Z13: =IF(OR(Y13="",Y13=0),H13*0.0118*CEILING((TODAY()-DATE(2026,8,22))/7,1),IF(DATE(VALUE(RIGHT(Y13,4)),VALUE(MID(Y13,4,2)),VALUE(LEFT(Y13,2)))<=DATE(2026,8,24),0,H13*0.0118*CEILING((DATE(VALUE(RIGHT(Y13,4)),VALUE(MID(Y13,4,2)),VALUE(LEFT(Y13,2)))-DATE(2026,8,22))/7,1))) -> 0 | AC13: =U13+X13+AA13 -> 20589 | AD13: =S13-AC13 -> 0 | AE13: DR2640100018 | AF13: 1800003156 | AG13: 14.08.2026
A14: 1 | B14: SCRAP POWER TRANSFORMER | C14: 3857116 | D14: 21977 | E14: NO | F14: 2007 | G14: SHAR JAHAN TRADERS | H14: 3857116 | I14: =ROUND(H14*18%,0) -> 694281 | J14: =+H14+I14 -> 4551397 | K14: =ROUND((H14+I14)*2%,0) -> 91028 | L14: =H14*0.1% -> 3857.116 | M14: =H14*2.25%*118% -> 102406.43 | N14: =H14*2.25%*2% -> 1735.7022 | O14: =M14-N14 -> 100670.73 | P14: =ROUND(O14+L14,0) -> 104528 | Q14: 0 | R14: =ROUND(H14*Q14,0) -> 0 | S14: =ROUND(H14*117.65%-R14,0) -> 4537897 | T14: =ROUND(H14*25%,0) -> 964279 | U14: =+T14 -> 964279 | V14: 13.08.2026 | W14: =ROUND(H14*92.65%-R14,0) -> 3573618 | X14: 3573618.9 | Y14: 13.08.2026 | Z14: =IF(OR(Y14="",Y14=0),H14*0.0118*CEILING((TODAY()-DATE(2026,8,22))/7,1),IF(DATE(VALUE(RIGHT(Y14,4)),VALUE(MID(Y14,4,2)),VALUE(LEFT(Y14,2)))<=DATE(2026,8,24),0,H14*0.0118*CEILING((DATE(VALUE(RIGHT(Y14,4)),VALUE(MID(Y14,4,2)),VALUE(LEFT(Y14,2)))-DATE(2026,8,22))/7,1))) -> 0 | AC14: =U14+X14+AA14 -> 4537897.9 | AD14: =S14-AC14 -> -0.90570839 | AE14: DR2640100024 | AF14: 1800003196 | AG14: 17.08.2026
A15: 250 | B15: Scrap of empty oil Druam | C15: 543 | D15: 21977 | E15: NO | F15: 2008 | G15: HIND TRADERS | H15: 135750 | I15: =ROUND(H15*18%,0) -> 24435 | J15: =+H15+I15 -> 160185 | K15: =ROUND((H15+I15)*2%,0) -> 3204 | L15: =H15*0.1% -> 135.75 | M15: =H15*2.25%*118% -> 3604.1625 | N15: =H15*2.25%*2% -> 61.0875 | O15: =M15-N15 -> 3543.075 | P15: =ROUND(O15+L15,0) -> 3679 | Q15: 0 | R15: =ROUND(H15*Q15,0) -> 0 | S15: =ROUND(H15*117.65%-R15,0) -> 159710 | T15: =ROUND(H15*25%,0) -> 33938 | U15: 33938 | V15: 14.08.2026 | W15: =ROUND(H15*92.65%-R15,0) -> 125772 | X15: 125772 | Y15: 18.08.2026 | Z15: =IF(OR(Y15="",Y15=0),H15*0.0118*CEILING((TODAY()-DATE(2026,8,22))/7,1),IF(DATE(VALUE(RIGHT(Y15,4)),VALUE(MID(Y15,4,2)),VALUE(LEFT(Y15,2)))<=DATE(2026,8,24),0,H15*0.0118*CEILING((DATE(VALUE(RIGHT(Y15,4)),VALUE(MID(Y15,4,2)),VALUE(LEFT(Y15,2)))-DATE(2026,8,22))/7,1))) -> 0 | AC15: =U15+X15+AA15 -> 159710 | AD15: =S15-AC15 -> 0 | AE15: DR2640100026 | AF15: 1800003247 | AG15: 20.08.2026
A16: 22 | B16: Scrap of empty oil Barrel | C16: 700 | D16: 21977 | E16: NO | F16: 2011 | G16: STERLING ENTERPRISES | H16: 15400 | I16: =ROUND(H16*18%,0) -> 2772 | J16: =+H16+I16 -> 18172 | K16: =ROUND((H16+I16)*2%,0) -> 363 | L16: =H16*0.1% -> 15.4 | M16: =H16*2.25%*118% -> 408.87 | N16: =H16*2.25%*2% -> 6.93 | O16: =M16-N16 -> 401.94 | P16: =ROUND(O16+L16,0) -> 417 | Q16: 0 | R16: =ROUND(H16*Q16,0) -> 0 | S16: =ROUND(H16*117.65%-R16,0) -> 18118 | T16: =ROUND(H16*25%,0) -> 3850 | U16: 3850 | V16: 11.08.2026 | W16: =ROUND(H16*92.65%-R16,0) -> 14268 | X16: 14267 | Y16: 11.08.2026 | Z16: =IF(OR(Y16="",Y16=0),H16*0.0118*CEILING((TODAY()-DATE(2026,8,22))/7,1),IF(DATE(VALUE(RIGHT(Y16,4)),VALUE(MID(Y16,4,2)),VALUE(LEFT(Y16,2)))<=DATE(2026,8,24),0,H16*0.0118*CEILING((DATE(VALUE(RIGHT(Y16,4)),VALUE(MID(Y16,4,2)),VALUE(LEFT(Y16,2)))-DATE(2026,8,22))/7,1))) -> 0 | AC16: =U16+X16+AA16 -> 18117 | AD16: =S16-AC16 -> 1 | AE16: DR2640100019 | AF16: 1800003157 | AG16: 14.08.2026
A17: 100 | B17: Scrap of empty oil Barrels | C17: 710 | D17: 21978 | E17: NO | F17: 2015 | G17: STERLING ENTERPRISES | H17: 71000 | I17: =ROUND(H17*18%,0) -> 12780 | J17: =+H17+I17 -> 83780 | K17: =ROUND((H17+I17)*2%,0) -> 1676 | L17: =H17*0.1% -> 71 | M17: =H17*2.25%*118% -> 1885.05 | N17: =H17*2.25%*2% -> 31.95 | O17: =M17-N17 -> 1853.1 | P17: =ROUND(O17+L17,0) -> 1924 | Q17: 0 | R17: =ROUND(H17*Q17,0) -> 0 | S17: =ROUND(H17*117.65%-R17,0) -> 83532 | T17: =ROUND(H17*25%,0) -> 17750 | U17: 17750 | V17: 11.08.2026 | W17: =ROUND(H17*92.65%-R17,0) -> 65782 | X17: =+W17 -> 65782 | Y17: 11.08.2026 | Z17: =IF(OR(Y17="",Y17=0),H17*0.0118*CEILING((TODAY()-DATE(2026,8,22))/7,1),IF(DATE(VALUE(RIGHT(Y17,4)),VALUE(MID(Y17,4,2)),VALUE(LEFT(Y17,2)))<=DATE(2026,8,24),0,H17*0.0118*CEILING((DATE(VALUE(RIGHT(Y17,4)),VALUE(MID(Y17,4,2)),VALUE(LEFT(Y17,2)))-DATE(2026,8,22))/7,1))) -> 0 | AC17: =U17+X17+AA17 -> 83532 | AD17: =S17-AC17 -> 0 | AE17: DR2640100020 | AF17: 1800003158 | AG17: 14.08.2026
A18: 1 | B18: Scrap of 220 KV Circuit Breaker | C18: 220001 | D18: 21978 | E18: NO | F18: 2018 | G18: NATIONAL ENTERPRISES | H18: 220001 | I18: =ROUND(H18*18%,0) -> 39600 | J18: =+H18+I18 -> 259601 | K18: =ROUND((H18+I18)*2%,0) -> 5192 | L18: =H18*0.1% -> 220.001 | M18: =H18*2.25%*118% -> 5841.0265 | N18: =H18*2.25%*2% -> 99.00045 | O18: =M18-N18 -> 5742.0261 | P18: =ROUND(O18+L18,0) -> 5962 | Q18: 0 | R18: =ROUND(H18*Q18,0) -> 0 | S18: =ROUND(H18*117.65%-R18,0) -> 258831 | T18: =ROUND(H18*25%,0) -> 55000 | U18: =+T18 -> 55000 | V18: 13.08.2026 | W18: =ROUND(H18*92.65%-R18,0) -> 203831 | X18: 203831 | Y18: 24.08.2026 | Z18: =IF(OR(Y18="",Y18=0),H18*0.0118*CEILING((TODAY()-DATE(2026,8,22))/7,1),IF(DATE(VALUE(RIGHT(Y18,4)),VALUE(MID(Y18,4,2)),VALUE(LEFT(Y18,2)))<=DATE(2026,8,24),0,H18*0.0118*CEILING((DATE(VALUE(RIGHT(Y18,4)),VALUE(MID(Y18,4,2)),VALUE(LEFT(Y18,2)))-DATE(2026,8,22))/7,1))) -> 0 | AC18: =U18+X18+AA18 -> 258831 | AD18: =S18-AC18 -> 0 | AE18: DR2640100034 | AF18: 1800003306 | AG18: 27.08.2026
A19: 1 | B19: Scrap of 220 KV Circuit Breaker | C19: 210001 | D19: 21978 | E19: NO | F19: 2019 | G19: NATIONAL ENTERPRISES | H19: 210001 | I19: =ROUND(H19*18%,0) -> 37800 | J19: =+H19+I19 -> 247801 | K19: =ROUND((H19+I19)*2%,0) -> 4956 | L19: =H19*0.1% -> 210.001 | M19: =H19*2.25%*118% -> 5575.5265 | N19: =H19*2.25%*2% -> 94.50045 | O19: =M19-N19 -> 5481.0261 | P19: =ROUND(O19+L19,0) -> 5691 | Q19: 0 | R19: =ROUND(H19*Q19,0) -> 0 | S19: =ROUND(H19*117.65%-R19,0) -> 247066 | T19: =ROUND(H19*25%,0) -> 52500 | U19: =+T19 -> 52500 | V19: 13.08.2026 | W19: =ROUND(H19*92.65%-R19,0) -> 194566 | X19: 194566 | Y19: 24.08.2026 | Z19: =IF(OR(Y19="",Y19=0),H19*0.0118*CEILING((TODAY()-DATE(2026,8,22))/7,1),IF(DATE(VALUE(RIGHT(Y19,4)),VALUE(MID(Y19,4,2)),VALUE(LEFT(Y19,2)))<=DATE(2026,8,24),0,H19*0.0118*CEILING((DATE(VALUE(RIGHT(Y19,4)),VALUE(MID(Y19,4,2)),VALUE(LEFT(Y19,2)))-DATE(2026,8,22))/7,1))) -> 0 | AC19: =U19+X19+AA19 -> 247066 | AD19: =S19-AC19 -> 0 | AE19: DR2640100035 | AF19: 1800003307 | AG19: 27.08.2026
A20: 3500 | B20: SCRAP 80MM² AAAC EARTHWIRE | C20: 333 | D20: 21978 | E20: KG | F20: 2020 | G20: OMKAR STEELS | H20: 1165500 | I20: =ROUND(H20*18%,0) -> 209790 | J20: =+H20+I20 -> 1375290 | K20: =ROUND((H20+I20)*2%,0) -> 27506 | L20: =H20*0.1% -> 1165.5 | M20: =H20*2.25%*118% -> 30944.025 | N20: =H20*2.25%*2% -> 524.475 | O20: =M20-N20 -> 30419.55 | P20: =ROUND(O20+L20,0) -> 31585 | Q20: 0.02 | R20: =ROUND(H20*Q20,0) -> 23310 | S20: =ROUND(H20*117.65%-R20,0) -> 1347901 | T20: =ROUND(H20*25%,0) -> 291375 | U20: 291375 | V20: 10.08.2026 | W20: =ROUND(H20*92.65%-R20,0) -> 1056526 | X20: 1056525 | Y20: 10.08.2026 | Z20: =IF(OR(Y20="",Y20=0),H20*0.0118*CEILING((TODAY()-DATE(2026,8,22))/7,1),IF(DATE(VALUE(RIGHT(Y20,4)),VALUE(MID(Y20,4,2)),VALUE(LEFT(Y20,2)))<=DATE(2026,8,24),0,H20*0.0118*CEILING((DATE(VALUE(RIGHT(Y20,4)),VALUE(MID(Y20,4,2)),VALUE(LEFT(Y20,2)))-DATE(2026,8,22))/7,1))) -> 0 | AC20: =U20+X20+AA20 -> 1347900 | AD20: =S20-AC20 -> 1 | AE20: DR2640100017 | AF20: 1800003065 | AG20: 12.08.2026
A21: 3 | B21: Scrap of 132 KV CT | C21: 110200 | D21: 21978 | E21: NO | F21: 2022 | G21: NATIONAL SCRAP AND BUILDING MATERIAL SUPPLIER | H21: 330600 | I21: =ROUND(H21*18%,0) -> 59508 | J21: =+H21+I21 -> 390108 | K21: =ROUND((H21+I21)*2%,0) -> 7802 | L21: =H21*0.1% -> 330.6 | M21: =H21*2.25%*118% -> 8777.43 | N21: =H21*2.25%*2% -> 148.77 | O21: =M21-N21 -> 8628.66 | P21: =ROUND(O21+L21,0) -> 8959 | Q21: 0 | R21: =ROUND(H21*Q21,0) -> 0 | S21: =ROUND(H21*117.65%-R21,0) -> 388951 | T21: =ROUND(H21*25%,0) -> 82650 | U21: =+T21 -> 82650 | V21: 14.08.2026 | W21: =ROUND(H21*92.65%-R21,0) -> 306301 | X21: 306301 | Y21: 21.08.2026 | Z21: =IF(OR(Y21="",Y21=0),H21*0.0118*CEILING((TODAY()-DATE(2026,8,22))/7,1),IF(DATE(VALUE(RIGHT(Y21,4)),VALUE(MID(Y21,4,2)),VALUE(LEFT(Y21,2)))<=DATE(2026,8,24),0,H21*0.0118*CEILING((DATE(VALUE(RIGHT(Y21,4)),VALUE(MID(Y21,4,2)),VALUE(LEFT(Y21,2)))-DATE(2026,8,22))/7,1))) -> 0 | AC21: =U21+X21+AA21 -> 388951 | AD21: =S21-AC21 -> 0 | AE21: DR2640100028 | AF21: 1800003269 | AG21: 24.08.2026
A22: 3 | B22: Scrap of 132 KV CT | C22: 83743 | D22: 21978 | E22: NO | F22: 2023 | G22: NATIONAL ENTERPRISES | H22: 251229 | I22: =ROUND(H22*18%,0) -> 45221 | J22: =+H22+I22 -> 296450 | K22: =ROUND((H22+I22)*2%,0) -> 5929 | L22: =H22*0.1% -> 251.229 | M22: =H22*2.25%*118% -> 6670.1299 | N22: =H22*2.25%*2% -> 113.05305 | O22: =M22-N22 -> 6557.0769 | P22: =ROUND(O22+L22,0) -> 6808 | Q22: 0 | R22: =ROUND(H22*Q22,0) -> 0 | S22: =ROUND(H22*117.65%-R22,0) -> 295571 | T22: =ROUND(H22*25%,0) -> 62807 | U22: =+T22 -> 62807 | V22: 13.08.2026 | W22: =ROUND(H22*92.65%-R22,0) -> 232764 | X22: 232764 | Y22: 24.08.2026 | Z22: =IF(OR(Y22="",Y22=0),H22*0.0118*CEILING((TODAY()-DATE(2026,8,22))/7,1),IF(DATE(VALUE(RIGHT(Y22,4)),VALUE(MID(Y22,4,2)),VALUE(LEFT(Y22,2)))<=DATE(2026,8,24),0,H22*0.0118*CEILING((DATE(VALUE(RIGHT(Y22,4)),VALUE(MID(Y22,4,2)),VALUE(LEFT(Y22,2)))-DATE(2026,8,22))/7,1))) -> 0 | AC22: =U22+X22+AA22 -> 295571 | AD22: =S22-AC22 -> 0 | AE22: DR2640100044 | AF22: 1800003308 | AG22: 27.08.2026
A23: 90 | B23: Scrap of empty oil Barrels | C23: 700 | D23: 21978 | E23: NO | F23: 2025 | G23: STERLING ENTERPRISES | H23: 63000 | I23: =ROUND(H23*18%,0) -> 11340 | J23: =+H23+I23 -> 74340 | K23: =ROUND((H23+I23)*2%,0) -> 1487 | L23: =H23*0.1% -> 63 | M23: =H23*2.25%*118% -> 1672.65 | N23: =H23*2.25%*2% -> 28.35 | O23: =M23-N23 -> 1644.3 | P23: =ROUND(O23+L23,0) -> 1707 | Q23: 0 | R23: =ROUND(H23*Q23,0) -> 0 | S23: =ROUND(H23*117.65%-R23,0) -> 74120 | T23: =ROUND(H23*25%,0) -> 15750 | U23: 15750 | V23: 11.08.2026 | W23: =ROUND(H23*92.65%-R23,0) -> 58370 | X23: 58418 | Y23: 11.08.2026 | Z23: =IF(OR(Y23="",Y23=0),H23*0.0118*CEILING((TODAY()-DATE(2026,8,22))/7,1),IF(DATE(VALUE(RIGHT(Y23,4)),VALUE(MID(Y23,4,2)),VALUE(LEFT(Y23,2)))<=DATE(2026,8,24),0,H23*0.0118*CEILING((DATE(VALUE(RIGHT(Y23,4)),VALUE(MID(Y23,4,2)),VALUE(LEFT(Y23,2)))-DATE(2026,8,22))/7,1))) -> 0 | AC23: =U23+X23+AA23 -> 74168 | AD23: =S23-AC23 -> -48 | AE23: DR2640100021 | AF23: 1800003160 | AG23: 14.08.2026
A24: 1 | B24: Scrap of 132 KV CT | C24: 50003 | D24: 21978 | E24: NO | F24: 2027 | G24: NATIONAL ENTERPRISES | H24: 50003 | I24: =ROUND(H24*18%,0) -> 9001 | J24: =+H24+I24 -> 59004 | K24: =ROUND((H24+I24)*2%,0) -> 1180 | L24: =H24*0.1% -> 50.003 | M24: =H24*2.25%*118% -> 1327.5796 | N24: =H24*2.25%*2% -> 22.50135 | O24: =M24-N24 -> 1305.0783 | P24: =ROUND(O24+L24,0) -> 1355 | Q24: 0 | R24: =ROUND(H24*Q24,0) -> 0 | S24: =ROUND(H24*117.65%-R24,0) -> 58829 | T24: =ROUND(H24*25%,0) -> 12501 | U24: =+T24 -> 12501 | V24: 13.08.2026 | W24: =ROUND(H24*92.65%-R24,0) -> 46328 | X24: 46328 | Y24: 24.08.2026 | Z24: =IF(OR(Y24="",Y24=0),H24*0.0118*CEILING((TODAY()-DATE(2026,8,22))/7,1),IF(DATE(VALUE(RIGHT(Y24,4)),VALUE(MID(Y24,4,2)),VALUE(LEFT(Y24,2)))<=DATE(2026,8,24),0,H24*0.0118*CEILING((DATE(VALUE(RIGHT(Y24,4)),VALUE(MID(Y24,4,2)),VALUE(LEFT(Y24,2)))-DATE(2026,8,22))/7,1))) -> 0 | AC24: =U24+X24+AA24 -> 58829 | AD24: =S24-AC24 -> 0 | AE24: DR2640100036 | AF24: 1800003309 | AG24: 27.08.2026
A25: 1000 | B25: Scrap Empty Oil Drum/ Barrel | C25: 517 | D25: 21978 | E25: NO | F25: 2033 | G25: WATAN SCRAP TRADERS | H25: 517000 | I25: =ROUND(H25*18%,0) -> 93060 | J25: =+H25+I25 -> 610060 | K25: =ROUND((H25+I25)*2%,0) -> 12201 | L25: =H25*0.1% -> 517 | M25: =H25*2.25%*118% -> 13726.35 | N25: =H25*2.25%*2% -> 232.65 | O25: =M25-N25 -> 13493.7 | P25: =ROUND(O25+L25,0) -> 14011 | Q25: 0 | R25: =ROUND(H25*Q25,0) -> 0 | S25: =ROUND(H25*117.65%-R25,0) -> 608251 | T25: =ROUND(H25*25%,0) -> 129250 | U25: 129250 | V25: 14.08.2026 | W25: =ROUND(H25*92.65%-R25,0) -> 479001 | X25: 479001 | Y25: 21.08.2026 | Z25: =IF(OR(Y25="",Y25=0),H25*0.0118*CEILING((TODAY()-DATE(2026,8,22))/7,1),IF(DATE(VALUE(RIGHT(Y25,4)),VALUE(MID(Y25,4,2)),VALUE(LEFT(Y25,2)))<=DATE(2026,8,24),0,H25*0.0118*CEILING((DATE(VALUE(RIGHT(Y25,4)),VALUE(MID(Y25,4,2)),VALUE(LEFT(Y25,2)))-DATE(2026,8,22))/7,1))) -> 0 | AC25: =U25+X25+AA25 -> 608251 | AD25: =S25-AC25 -> 0 | AE25: DR2640100042 | AF25: 1800003317 | AG25: 27.08.2026
A26: 2 | B26: Scrap of 132 KV Wave Trap | C26: 14001 | D26: 21978 | E26: NO | F26: 2035 | G26: NATIONAL ENTERPRISES | H26: 28002 | I26: =ROUND(H26*18%,0) -> 5040 | J26: =+H26+I26 -> 33042 | K26: =ROUND((H26+I26)*2%,0) -> 661 | L26: =H26*0.1% -> 28.002 | M26: =H26*2.25%*118% -> 743.4531 | N26: =H26*2.25%*2% -> 12.6009 | O26: =M26-N26 -> 730.8522 | P26: =ROUND(O26+L26,0) -> 759 | Q26: 0 | R26: =ROUND(H26*Q26,0) -> 0 | S26: =ROUND(H26*117.65%-R26,0) -> 32944 | T26: =ROUND(H26*25%,0) -> 7001 | U26: =+T26 -> 7001 | V26: 13.08.2026 | W26: =ROUND(H26*92.65%-R26,0) -> 25944 | X26: 25943 | Y26: 24.08.2026 | Z26: =IF(OR(Y26="",Y26=0),H26*0.0118*CEILING((TODAY()-DATE(2026,8,22))/7,1),IF(DATE(VALUE(RIGHT(Y26,4)),VALUE(MID(Y26,4,2)),VALUE(LEFT(Y26,2)))<=DATE(2026,8,24),0,H26*0.0118*CEILING((DATE(VALUE(RIGHT(Y26,4)),VALUE(MID(Y26,4,2)),VALUE(LEFT(Y26,2)))-DATE(2026,8,22))/7,1))) -> 0 | AC26: =U26+X26+AA26 -> 32944 | AD26: =S26-AC26 -> 0 | AE26: DR2640100037 | AF26: 1800003310 | AG26: 27.08.2026
A27: 8.2 | B27: Mix Scrap (Tower angles & 0.2 ACSR Condutor pieces) | C27: 67000 | D27: 21978 | E27: MT | F27: 2036 | G27: M I SCRAP TRADERS | H27: 549400 | I27: =ROUND(H27*18%,0) -> 98892 | J27: =+H27+I27 -> 648292 | K27: =ROUND((H27+I27)*2%,0) -> 12966 | L27: =H27*0.1% -> 549.4 | M27: =H27*2.25%*118% -> 14586.57 | N27: =H27*2.25%*2% -> 247.23 | O27: =M27-N27 -> 14339.34 | P27: =ROUND(O27+L27,0) -> 14889 | Q27: 0.02 | R27: =ROUND(H27*Q27,0) -> 10988 | S27: =ROUND(H27*117.65%-R27,0) -> 635381 | T27: =ROUND(H27*25%,0) -> 137350 | U27: 137350 | V27: 14.08.2026 | W27: =ROUND(H27*92.65%-R27,0) -> 498031 | Y27: 0 | Z27: =IF(OR(Y27="",Y27=0),H27*0.0118*CEILING((TODAY()-DATE(2026,8,22))/7,1),IF(DATE(VALUE(RIGHT(Y27,4)),VALUE(MID(Y27,4,2)),VALUE(LEFT(Y27,2)))<=DATE(2026,8,24),0,H27*0.0118*CEILING((DATE(VALUE(RIGHT(Y27,4)),VALUE(MID(Y27,4,2)),VALUE(LEFT(Y27,2)))-DATE(2026,8,22))/7,1))) -> 19448.76 | AC27: =U27+X27+AA27 -> 137350 | AD27: =S27-AC27 -> 498031
A28: 50 | B28: Scrap of empty oil Barrels | C28: 531 | D28: 21978 | E28: NO | F28: 2037 | G28: WATAN SCRAP TRADERS | H28: 26550 | I28: =ROUND(H28*18%,0) -> 4779 | J28: =+H28+I28 -> 31329 | K28: =ROUND((H28+I28)*2%,0) -> 627 | L28: =H28*0.1% -> 26.55 | M28: =H28*2.25%*118% -> 704.9025 | N28: =H28*2.25%*2% -> 11.9475 | O28: =M28-N28 -> 692.955 | P28: =ROUND(O28+L28,0) -> 720 | Q28: 0 | R28: =ROUND(H28*Q28,0) -> 0 | S28: =ROUND(H28*117.65%-R28,0) -> 31236 | T28: =ROUND(H28*25%,0) -> 6638 | U28: 6638 | V28: 14.08.2026 | W28: =ROUND(H28*92.65%-R28,0) -> 24599 | X28: 24598 | Y28: 21.08.2026 | Z28: =IF(OR(Y28="",Y28=0),H28*0.0118*CEILING((TODAY()-DATE(2026,8,22))/7,1),IF(DATE(VALUE(RIGHT(Y28,4)),VALUE(MID(Y28,4,2)),VALUE(LEFT(Y28,2)))<=DATE(2026,8,24),0,H28*0.0118*CEILING((DATE(VALUE(RIGHT(Y28,4)),VALUE(MID(Y28,4,2)),VALUE(LEFT(Y28,2)))-DATE(2026,8,22))/7,1))) -> 0 | AC28: =U28+X28+AA28 -> 31236 | AD28: =S28-AC28 -> 0 | AE28: DR2640100043 | AF28: 1800003318 | AG28: 27.08.2026
A29: 3 | B29: Scrap of 33 KV CT | C29: 90002 | D29: 21978 | E29: NO | F29: 2040 | G29: STERLING ENTERPRISES | H29: 270006 | I29: =ROUND(H29*18%,0) -> 48601 | J29: =+H29+I29 -> 318607 | K29: =ROUND((H29+I29)*2%,0) -> 6372 | L29: =H29*0.1% -> 270.006 | M29: =H29*2.25%*118% -> 7168.6593 | N29: =H29*2.25%*2% -> 121.5027 | O29: =M29-N29 -> 7047.1566 | P29: =ROUND(O29+L29,0) -> 7317 | Q29: 0 | R29: =ROUND(H29*Q29,0) -> 0 | S29: =ROUND(H29*117.65%-R29,0) -> 317662 | T29: =ROUND(H29*25%,0) -> 67502 | U29: 67502 | V29: 11.08.2026 | W29: =ROUND(H29*92.65%-R29,0) -> 250161 | Y29: 0 | Z29: =IF(OR(Y29="",Y29=0),H29*0.0118*CEILING((TODAY()-DATE(2026,8,22))/7,1),IF(DATE(VALUE(RIGHT(Y29,4)),VALUE(MID(Y29,4,2)),VALUE(LEFT(Y29,2)))<=DATE(2026,8,24),0,H29*0.0118*CEILING((DATE(VALUE(RIGHT(Y29,4)),VALUE(MID(Y29,4,2)),VALUE(LEFT(Y29,2)))-DATE(2026,8,22))/7,1))) -> 9558.2124 | AC29: =U29+X29+AA29 -> 67502 | AD29: =S29-AC29 -> 250160
A30: 5 | B30: Scrap of 132 KV CT | C30: 80000 | D30: 21979 | E30: NO | F30: 2043 | G30: NATIONAL ENTERPRISES | H30: 400000 | I30: =ROUND(H30*18%,0) -> 72000 | J30: =+H30+I30 -> 472000 | K30: =ROUND((H30+I30)*2%,0) -> 9440 | L30: =H30*0.1% -> 400 | M30: =H30*2.25%*118% -> 10620 | N30: =H30*2.25%*2% -> 180 | O30: =M30-N30 -> 10440 | P30: =ROUND(O30+L30,0) -> 10840 | Q30: 0 | R30: =ROUND(H30*Q30,0) -> 0 | S30: =ROUND(H30*117.65%-R30,0) -> 470600 | T30: =ROUND(H30*25%,0) -> 100000 | U30: =+T30 -> 100000 | V30: 13.08.2026 | W30: =ROUND(H30*92.65%-R30,0) -> 370600 | X30: 370600 | Y30: 24.08.2026 | Z30: =IF(OR(Y30="",Y30=0),H30*0.0118*CEILING((TODAY()-DATE(2026,8,22))/7,1),IF(DATE(VALUE(RIGHT(Y30,4)),VALUE(MID(Y30,4,2)),VALUE(LEFT(Y30,2)))<=DATE(2026,8,24),0,H30*0.0118*CEILING((DATE(VALUE(RIGHT(Y30,4)),VALUE(MID(Y30,4,2)),VALUE(LEFT(Y30,2)))-DATE(2026,8,22))/7,1))) -> 0 | AC30: =U30+X30+AA30 -> 470600 | AD30: =S30-AC30 -> 0 | AE30: DR2640100038 | AF30: 1800003311 | AG30: 27.08.2026
A31: 670 | B31: Scrap of AAAC Earth wire | C31: 309 | D31: 21979 | E31: KG | F31: 2046 | G31: SAHARA ENTERPRISES | H31: 207030 | I31: =ROUND(H31*18%,0) -> 37265 | J31: =+H31+I31 -> 244295 | K31: =ROUND((H31+I31)*2%,0) -> 4886 | L31: =H31*0.1% -> 207.03 | M31: =H31*2.25%*118% -> 5496.6465 | N31: =H31*2.25%*2% -> 93.1635 | O31: =M31-N31 -> 5403.483 | P31: =ROUND(O31+L31,0) -> 5611 | Q31: 0 | R31: =ROUND(H31*Q31,0) -> 0 | S31: =ROUND(H31*117.65%-R31,0) -> 243571 | T31: =ROUND(H31*25%,0) -> 51758 | U31: 51758 | V31: 11.08.2026 | W31: =ROUND(H31*92.65%-R31,0) -> 191813 | X31: 191812 | Y31: 21.08.2026 | Z31: =IF(OR(Y31="",Y31=0),H31*0.0118*CEILING((TODAY()-DATE(2026,8,22))/7,1),IF(DATE(VALUE(RIGHT(Y31,4)),VALUE(MID(Y31,4,2)),VALUE(LEFT(Y31,2)))<=DATE(2026,8,24),0,H31*0.0118*CEILING((DATE(VALUE(RIGHT(Y31,4)),VALUE(MID(Y31,4,2)),VALUE(LEFT(Y31,2)))-DATE(2026,8,22))/7,1))) -> 0 | AC31: =U31+X31+AA31 -> 243570 | AD31: =S31-AC31 -> 1 | AE31: DR2640100041 | AF31: 1800003316 | AG31: 27.08.2026
A32: 2 | B32: Scrap of 220 KV CT | C32: 80006 | D32: 21979 | E32: NO | F32: 2055 | G32: NATIONAL ENTERPRISES | H32: 160012 | I32: =ROUND(H32*18%,0) -> 28802 | J32: =+H32+I32 -> 188814 | K32: =ROUND((H32+I32)*2%,0) -> 3776 | L32: =H32*0.1% -> 160.012 | M32: =H32*2.25%*118% -> 4248.3186 | N32: =H32*2.25%*2% -> 72.0054 | O32: =M32-N32 -> 4176.3132 | P32: =ROUND(O32+L32,0) -> 4336 | Q32: 0 | R32: =ROUND(H32*Q32,0) -> 0 | S32: =ROUND(H32*117.65%-R32,0) -> 188254 | T32: =ROUND(H32*25%,0) -> 40003 | U32: =+T32 -> 40003 | V32: 13.08.2026 | W32: =ROUND(H32*92.65%-R32,0) -> 148251 | X32: 148251 | Y32: 24.08.2026 | Z32: =IF(OR(Y32="",Y32=0),H32*0.0118*CEILING((TODAY()-DATE(2026,8,22))/7,1),IF(DATE(VALUE(RIGHT(Y32,4)),VALUE(MID(Y32,4,2)),VALUE(LEFT(Y32,2)))<=DATE(2026,8,24),0,H32*0.0118*CEILING((DATE(VALUE(RIGHT(Y32,4)),VALUE(MID(Y32,4,2)),VALUE(LEFT(Y32,2)))-DATE(2026,8,22))/7,1))) -> 0 | AC32: =U32+X32+AA32 -> 188254 | AD32: =S32-AC32 -> 0 | AE32: DR2640100039 | AF32: 1800003312 | AG32: 27.08.2026
A33: 1 | B33: Scrap of 33 KV GCB | C33: 29502 | D33: 21979 | E33: NO | F33: 2059 | G33: NATIONAL ENTERPRISES | H33: 29502 | I33: =ROUND(H33*18%,0) -> 5310 | J33: =+H33+I33 -> 34812 | K33: =ROUND((H33+I33)*2%,0) -> 696 | L33: =H33*0.1% -> 29.502 | M33: =H33*2.25%*118% -> 783.2781 | N33: =H33*2.25%*2% -> 13.2759 | O33: =M33-N33 -> 770.0022 | P33: =ROUND(O33+L33,0) -> 800 | Q33: 0 | R33: =ROUND(H33*Q33,0) -> 0 | S33: =ROUND(H33*117.65%-R33,0) -> 34709 | T33: =ROUND(H33*25%,0) -> 7376 | U33: =+T33 -> 7376 | V33: 13.08.2026 | W33: =ROUND(H33*92.65%-R33,0) -> 27334 | X33: 27332 | Y33: 24.08.2026 | Z33: =IF(OR(Y33="",Y33=0),H33*0.0118*CEILING((TODAY()-DATE(2026,8,22))/7,1),IF(DATE(VALUE(RIGHT(Y33,4)),VALUE(MID(Y33,4,2)),VALUE(LEFT(Y33,2)))<=DATE(2026,8,24),0,H33*0.0118*CEILING((DATE(VALUE(RIGHT(Y33,4)),VALUE(MID(Y33,4,2)),VALUE(LEFT(Y33,2)))-DATE(2026,8,22))/7,1))) -> 0 | AC33: =U33+X33+AA33 -> 34708 | AD33: =S33-AC33 -> 1 | AE33: DR2640100046 | AF33: 1800003313 | AG33: 27.08.2026
A34: 30 | B34: Scrap of Empty oil Barrels | C34: 702 | D34: 21979 | E34: NO | F34: 2062 | G34: STERLING ENTERPRISES | H34: 21060 | I34: =ROUND(H34*18%,0) -> 3791 | J34: =+H34+I34 -> 24851 | K34: =ROUND((H34+I34)*2%,0) -> 497 | L34: =H34*0.1% -> 21.06 | M34: =H34*2.25%*118% -> 559.143 | N34: =H34*2.25%*2% -> 9.477 | O34: =M34-N34 -> 549.666 | P34: =ROUND(O34+L34,0) -> 571 | Q34: 0 | R34: =ROUND(H34*Q34,0) -> 0 | S34: =ROUND(H34*117.65%-R34,0) -> 24777 | T34: =ROUND(H34*25%,0) -> 5265 | U34: 5265 | V34: 11.08.2026 | W34: =ROUND(H34*92.65%-R34,0) -> 19512 | X34: 19512 | Y34: 11.08.2026 | Z34: =IF(OR(Y34="",Y34=0),H34*0.0118*CEILING((TODAY()-DATE(2026,8,22))/7,1),IF(DATE(VALUE(RIGHT(Y34,4)),VALUE(MID(Y34,4,2)),VALUE(LEFT(Y34,2)))<=DATE(2026,8,24),0,H34*0.0118*CEILING((DATE(VALUE(RIGHT(Y34,4)),VALUE(MID(Y34,4,2)),VALUE(LEFT(Y34,2)))-DATE(2026,8,22))/7,1))) -> 0 | AC34: =U34+X34+AA34 -> 24777 | AD34: =S34-AC34 -> 0 | AE34: DR2640100022 | AF34: 1800003161 | AG34: 14.08.2026
A35: 150 | B35: Scrap of empty oil drums | C35: 571 | D35: 21980 | E35: NO | F35: 2067 | G35: WATAN SCRAP TRADERS | H35: 85650 | I35: =ROUND(H35*18%,0) -> 15417 | J35: =+H35+I35 -> 101067 | K35: =ROUND((H35+I35)*2%,0) -> 2021 | L35: =H35*0.1% -> 85.65 | M35: =H35*2.25%*118% -> 2274.0075 | N35: =H35*2.25%*2% -> 38.5425 | O35: =M35-N35 -> 2235.465 | P35: =ROUND(O35+L35,0) -> 2321 | Q35: 0 | R35: =ROUND(H35*Q35,0) -> 0 | S35: =ROUND(H35*117.65%-R35,0) -> 100767 | T35: =ROUND(H35*25%,0) -> 21413 | U35: 21413 | V35: 14.08.2026 | W35: =ROUND(H35*92.65%-R35,0) -> 79355 | X35: 79354 | Y35: 20.08.2026 | Z35: =IF(OR(Y35="",Y35=0),H35*0.0118*CEILING((TODAY()-DATE(2026,8,22))/7,1),IF(DATE(VALUE(RIGHT(Y35,4)),VALUE(MID(Y35,4,2)),VALUE(LEFT(Y35,2)))<=DATE(2026,8,24),0,H35*0.0118*CEILING((DATE(VALUE(RIGHT(Y35,4)),VALUE(MID(Y35,4,2)),VALUE(LEFT(Y35,2)))-DATE(2026,8,22))/7,1))) -> 0 | AC35: =U35+X35+AA35 -> 100767 | AD35: =S35-AC35 -> 0 | AE35: DR2640100027 | AF35: 1800003248 | AG35: 20.08.2026
A36: 1 | B36: Scrap of 33 KV CB | C36: 54000 | D36: 21980 | E36: NO | F36: 2069 | G36: STERLING ENTERPRISES | H36: 54000 | I36: =ROUND(H36*18%,0) -> 9720 | J36: =+H36+I36 -> 63720 | K36: =ROUND((H36+I36)*2%,0) -> 1274 | L36: =H36*0.1% -> 54 | M36: =H36*2.25%*118% -> 1433.7 | N36: =H36*2.25%*2% -> 24.3 | O36: =M36-N36 -> 1409.4 | P36: =ROUND(O36+L36,0) -> 1463 | Q36: 0 | R36: =ROUND(H36*Q36,0) -> 0 | S36: =ROUND(H36*117.65%-R36,0) -> 63531 | T36: =ROUND(H36*25%,0) -> 13500 | U36: 13500 | V36: 11.08.2026 | W36: =ROUND(H36*92.65%-R36,0) -> 50031 | Y36: 0 | Z36: =IF(OR(Y36="",Y36=0),H36*0.0118*CEILING((TODAY()-DATE(2026,8,22))/7,1),IF(DATE(VALUE(RIGHT(Y36,4)),VALUE(MID(Y36,4,2)),VALUE(LEFT(Y36,2)))<=DATE(2026,8,24),0,H36*0.0118*CEILING((DATE(VALUE(RIGHT(Y36,4)),VALUE(MID(Y36,4,2)),VALUE(LEFT(Y36,2)))-DATE(2026,8,22))/7,1))) -> 1911.6 | AC36: =U36+X36+AA36 -> 13500 | AD36: =S36-AC36 -> 50031
A37: 3 | B37: Scrap of 66 KV Isolater | C37: 25001 | D37: 21980 | E37: NO | F37: 2071 | G37: NATIONAL ENTERPRISES | H37: 75003 | I37: =ROUND(H37*18%,0) -> 13501 | J37: =+H37+I37 -> 88504 | K37: =ROUND((H37+I37)*2%,0) -> 1770 | L37: =H37*0.1% -> 75.003 | M37: =H37*2.25%*118% -> 1991.3296 | N37: =H37*2.25%*2% -> 33.75135 | O37: =M37-N37 -> 1957.5783 | P37: =ROUND(O37+L37,0) -> 2033 | Q37: 0 | R37: =ROUND(H37*Q37,0) -> 0 | S37: =ROUND(H37*117.65%-R37,0) -> 88241 | T37: =ROUND(H37*25%,0) -> 18751 | U37: =+T37 -> 18751 | V37: 13.08.2026 | W37: =ROUND(H37*92.65%-R37,0) -> 69490 | X37: 69491 | Y37: 24.08.2026 | Z37: =IF(OR(Y37="",Y37=0),H37*0.0118*CEILING((TODAY()-DATE(2026,8,22))/7,1),IF(DATE(VALUE(RIGHT(Y37,4)),VALUE(MID(Y37,4,2)),VALUE(LEFT(Y37,2)))<=DATE(2026,8,24),0,H37*0.0118*CEILING((DATE(VALUE(RIGHT(Y37,4)),VALUE(MID(Y37,4,2)),VALUE(LEFT(Y37,2)))-DATE(2026,8,22))/7,1))) -> 0 | AC37: =U37+X37+AA37 -> 88242 | AD37: =S37-AC37 -> -1 | AE37: DR2640100040 | AF37: 1800003314 | AG37: 27.08.2026
A38: 3 | B38: Scrap of 132 KV CT | C38: 70001 | D38: 21980 | E38: NO | F38: 2086 | G38: KASHYAP TRADING CO | H38: 210003 | I38: =ROUND(H38*18%,0) -> 37801 | J38: =+H38+I38 -> 247804 | K38: =ROUND((H38+I38)*2%,0) -> 4956 | L38: =H38*0.1% -> 210.003 | M38: =H38*2.25%*118% -> 5575.5796 | N38: =H38*2.25%*2% -> 94.50135 | O38: =M38-N38 -> 5481.0783 | P38: =ROUND(O38+L38,0) -> 5691 | Q38: 0 | R38: =ROUND(H38*Q38,0) -> 0 | S38: =ROUND(H38*117.65%-R38,0) -> 247069 | T38: =ROUND(H38*25%,0) -> 52501 | U38: 52501 | V38: 17.08.2026 | W38: =ROUND(H38*92.65%-R38,0) -> 194568 | X38: 194568 | Y38: 17.08.2026 | Z38: =IF(OR(Y38="",Y38=0),H38*0.0118*CEILING((TODAY()-DATE(2026,8,22))/7,1),IF(DATE(VALUE(RIGHT(Y38,4)),VALUE(MID(Y38,4,2)),VALUE(LEFT(Y38,2)))<=DATE(2026,8,24),0,H38*0.0118*CEILING((DATE(VALUE(RIGHT(Y38,4)),VALUE(MID(Y38,4,2)),VALUE(LEFT(Y38,2)))-DATE(2026,8,22))/7,1))) -> 0 | AC38: =U38+X38+AA38 -> 247069 | AD38: =S38-AC38 -> 0 | AE38: DR2640100025 | AF38: 1800003226 | AG38: 19.08.2026
A39: 2 | B39: Scrap of 66 kv TBC C & R Panel | C39: 15006 | D39: 21980 | E39: NO | F39: 2089 | G39: S M ENTERPRISES | H39: 30012 | I39: =ROUND(H39*18%,0) -> 5402 | J39: =+H39+I39 -> 35414 | K39: =ROUND((H39+I39)*2%,0) -> 708 | L39: =H39*0.1% -> 30.012 | M39: =H39*2.25%*118% -> 796.8186 | N39: =H39*2.25%*2% -> 13.5054 | O39: =M39-N39 -> 783.3132 | P39: =ROUND(O39+L39,0) -> 813 | Q39: 0 | R39: =ROUND(H39*Q39,0) -> 0 | S39: =ROUND(H39*117.65%-R39,0) -> 35309 | T39: =ROUND(H39*25%,0) -> 7503 | U39: 7503 | V39: 14.08.2026 | W39: =ROUND(H39*92.65%-R39,0) -> 27806 | X39: 27806 | Y39: 01.09.2026 | Z39: =IF(OR(Y39="",Y39=0),H39*0.0118*CEILING((TODAY()-DATE(2026,8,22))/7,1),IF(DATE(VALUE(RIGHT(Y39,4)),VALUE(MID(Y39,4,2)),VALUE(LEFT(Y39,2)))<=DATE(2026,8,24),0,H39*0.0118*CEILING((DATE(VALUE(RIGHT(Y39,4)),VALUE(MID(Y39,4,2)),VALUE(LEFT(Y39,2)))-DATE(2026,8,22))/7,1))) -> 708.2832 | AA39: 708 | AB39: 01.09.2026 | AC39: =U39+X39+AA39 -> 36017 | AD39: =S39-AC39 -> -708
A40: 3 | B40: Scrap of 132 KV CT | C40: 40003 | D40: 21980 | E40: NO | F40: 2091 | G40: S M ENTERPRISES | H40: 120009 | I40: =ROUND(H40*18%,0) -> 21602 | J40: =+H40+I40 -> 141611 | K40: =ROUND((H40+I40)*2%,0) -> 2832 | L40: =H40*0.1% -> 120.009 | M40: =H40*2.25%*118% -> 3186.2389 | N40: =H40*2.25%*2% -> 54.00405 | O40: =M40-N40 -> 3132.2349 | P40: =ROUND(O40+L40,0) -> 3252 | Q40: 0 | R40: =ROUND(H40*Q40,0) -> 0 | S40: =ROUND(H40*117.65%-R40,0) -> 141191 | T40: =ROUND(H40*25%,0) -> 30002 | U40: 30002 | V40: 14.08.2026 | W40: =ROUND(H40*92.65%-R40,0) -> 111188 | X40: 111189 | Y40: 01.09.2026 | Z40: =IF(OR(Y40="",Y40=0),H40*0.0118*CEILING((TODAY()-DATE(2026,8,22))/7,1),IF(DATE(VALUE(RIGHT(Y40,4)),VALUE(MID(Y40,4,2)),VALUE(LEFT(Y40,2)))<=DATE(2026,8,24),0,H40*0.0118*CEILING((DATE(VALUE(RIGHT(Y40,4)),VALUE(MID(Y40,4,2)),VALUE(LEFT(Y40,2)))-DATE(2026,8,22))/7,1))) -> 2832.2124 | AA40: 2832 | AB40: 01.09.2026 | AC40: =U40+X40+AA40 -> 144023 | AD40: =S40-AC40 -> -2832
H41: =SUM(H4:H40) -> 15130598 | I41: =SUM(I4:I40) -> 2723508 | J41: =SUM(J4:J40) -> 17854106 | K41: =SUM(K4:K40) -> 357082 | L41: =SUM(L4:L40) -> 15130.598 | M41: =SUM(M4:M40) -> 401717.38 | N41: =SUM(N4:N40) -> 6808.7691 | O41: =SUM(O4:O40) -> 394908.61 | P41: =SUM(P4:P40) -> 410039 | R41: =SUM(R4:R40) -> 83029 | S41: =SUM(S4:S40) -> 17718123 | T41: =SUM(T4:T40) -> 3782654 | U41: =SUM(U4:U40) -> 3782654 | W41: =SUM(W4:W40) -> 13935473 | X41: =SUM(X4:X40) -> 13137293 | Z41: =SUM(Z4:Z40) -> 34459.068 | AA41: =SUM(AA4:AA40) -> 3540 | AC41: =SUM(AC4:AC40) -> 16923487 | AD41: =SUM(AD4:AD40) -> 794636
...

Sheet Live Search
A1: MSTC LIMITED • LIVE SEARCH (results grouped by the value you typed, each group totalled, TOTAL MATCHED beneath them, the misses greyed in a REMAINING block, a GRAND TOTAL of both at the foot)
A2: HOW TO USE ▶ click the yellow box B3 and type - a lot number (1874), part of one (187), a buyer (NATIONAL), part of a buyer name, a lot name (COPPER). • WILDCARD / MATCH ANY - separate values with a comma or a slash: 1874, 1923, OMKAR or 1874 / 1923 - and every lot containing ANY of them lights up. • FACETED / FILTERED - separate them with + or &: NATIONAL + COPPER - and a lot lights up only if it matches EVERY facet. • the two mix: OMKAR, STERLING + COPPER = (OMKAR or STERLING) and COPPER. Up to 8 values, empty ones ignored, spaces around a separator are fine. • THE RESULT IS GROUPED BY THE VALUE YOU TYPED: every value gets its own block of lots with a shaded ∑ total row beneath it, then a blue TOTAL MATCHED row adds every group up at once - the grand total of the rows your search actually hit, sitting right beneath them. Under that a greyed REMAINING block holds the lots that did not match, with its own total, and the green GRAND TOTAL of both sits at the foot. A lot matching two values is counted under the first one only, so TOTAL MATCHED + REMAINING always equals GRAND TOTAL, and with nothing typed the matched row is the whole list. • clear the box and all 37 come back in one ALL LOTS block. • cell F3 narrows what the text is looked for in (lot no. + buyer + name by default). • matching is 'contains', not case sensitive. • nothing here is typed in: every figure is a live link to 'Final Calculation Sheet'. • columns AK..BL are hidden helpers.
A3: 🔍 SEARCH ▸ | B3: drum, barrel | E3: SEARCH IN ▸ | F3: Lot No. + Buyer + Name | G3: MATCHES ▸ | H3: =SUM($AM$5:$AM$41)&" of 37" -> 9 of 37 | I3: =IF($B$3="","◀ type in the yellow box - a lot no., a buyer, a lot name... several values: comma or / = ANY of them, + or & = ALL of them","matching "&SUM($AM$5:$AM$41)&" of 37 lots • search: "&$B$3&" • in: "&$F$3&" • grouped by the value typed, the misses greyed in REMAINING, TOTAL MATCHED totals the hits") -> matching 9 of 37 lots • search: drum, barrel • in: Lot No. + Buyer + Name • grouped by the value typed, the misses greyed in REMAINING, TOTAL MATCHED totals the hits | AK3: the text this lot is searched in | AM3: 1 = this lot matches the search box | AO3: the 'search in' list | AQ3: the box with & -> + and / -> , | AR3: term 1 - rows 4..9: text left, delimiter pos, the term, delimiter, running facet, facet no.
A4: # | B4: Lot No. | C4: Buyer | D4: Lot Name | E4: Bid Sheet | F4: Quantity | G4: Unit | H4: Rate | I4: Mat. Value | J4: GST | K4: Mat. Value + GST | L4: TCS | M4: TDS u/s 194(O) | N4: Service Charge to MSTC | O4: TDS u/s 194(H) | P4: Net Service Charge (post TDS 194H) | Q4: Service charge to MSTC | R4: GST TDS Rate | S4: GST TDS | T4: Total Receivables in Cash | U4: Security Deposit (Expected) | V4: Security Deposit (Received) | W4: Date of Receipt (col V) | X4: Final Payment (Expected) | Y4: Final Payment (Received) | Z4: Date of Receipt (col Y) | AA4: LPP Expected | AB4: LPP Received | AC4: Date of Recepit of LPP | AD4: Total Received | AE4: Outstanding | AF4: Invoice No. | AG4: SAP Document | AH4: Doc./Invoice Date | AI4: Payment Status | AO4: Lot No. + Buyer + Name | AQ4: =SUBSTITUTE(SUBSTITUTE($B$3,"&","+"),"/",",") -> drum, barrel | AR4: =$AQ$4 -> drum, barrel | AS4: =IF(OR($AR$4="",$AR$5=99999),"",MID($AR$4,$AR$5+1,99999)) -> barrel | AT4: =IF(OR($AS$4="",$AS$5=99999),"",MID($AS$4,$AS$5+1,99999)) | AU4: =IF(OR($AT$4="",$AT$5=99999),"",MID($AT$4,$AT$5+1,99999)) | AV4: =IF(OR($AU$4="",$AU$5=99999),"",MID($AU$4,$AU$5+1,99999)) | AW4: =IF(OR($AV$4="",$AV$5=99999),"",MID($AV$4,$AV$5+1,99999)) | AX4: =IF(OR($AW$4="",$AW$5=99999),"",MID($AW$4,$AW$5+1,99999)) | AY4: =IF(OR($AX$4="",$AX$5=99999),"",MID($AX$4,$AX$5+1,99999)) | BD4: =COUNTIF($AZ$5:$AZ$41,1) -> 4 | BE4: 5 | BF4: =IF($BD4=0,0,$BE4+$BD4) -> 9 | BG4: =IF($BD12=0,$BE12,$BF12+1) -> 16
A5: =IF($BJ5>0,INDEX($BA$5:$BA$41,MATCH(5,$BB$5:$BB$41,0)),IF(OR($BI5=1,$BL5=1,$BH5>0),"∑","")) -> 1 | B5: =IF($BJ5>0,IF(INDEX('Final Calculation Sheet'!$F$4:$F$40,$BJ5-3)="","",INDEX('Final Calculation Sheet'!$F$4:$F$40,$BJ5-3)),"") -> 1874 | C5: =IF($BJ5>0,IF(INDEX('Final Calculation Sheet'!$G$4:$G$40,$BJ5-3)="","",INDEX('Final Calculation Sheet'!$G$4:$G$40,$BJ5-3)),IF(OR($BI5=1,$BL5=1,$BH5>0),IF($BI5=1,37,IF($BL5=1,37-INDEX($BD$4:$BD$13,10),INDEX($BD$4:$BD$13,$BH5)))&" lot(s)","")) -> NATIONAL ENTERPRISES | D5: =IF($BJ5>0,IF(INDEX('Final Calculation Sheet'!$B$4:$B$40,$BJ5-3)="","",INDEX('Final Calculation Sheet'!$B$4:$B$40,$BJ5-3)),IF(OR($BI5=1,$BL5=1,$BH5>0),IF($BI5=1,"GRAND TOTAL — matching + remaining",IF($BL5=1,"TOTAL MATCHED — every group together",IF($BH5=10,"REMAINING — did not match the search",IF($BH5=9,"ALL LOTS — nothing typed in the box","GROUP "&$BH5&" TOTAL — lots matching "&INDEX($AR$6:$AY$6,$BH5))))),"")) -> Scrap of Empty oil drum | E5: =IF($BJ5>0,IF(INDEX('Final Calculation Sheet'!$D$4:$D$40,$BJ5-3)="","",INDEX('Final Calculation Sheet'!$D$4:$D$40,$BJ5-3)),IF(OR($BI5=1,$BL5=1,$BH5>0),"–","")) -> 21977 | F5: =IF($BJ5>0,IF(INDEX('Final Calculation Sheet'!$A$4:$A$40,$BJ5-3)="","",INDEX('Final Calculation Sheet'!$A$4:$A$40,$BJ5-3)),IF(OR($BI5=1,$BL5=1,$BH5>0),IF($BI5=1,SUM('Final Calculation Sheet'!$A$4:$A$40),IF($BL5=1,SUM('Final Calculation Sheet'!$A$4:$A$40)-SUMIFS('Final Calculation Sheet'!$A$4:$A$40,$AZ$5:$AZ$41,10),SUMIFS('Final Calculation Sheet'!$A$4:$A$40,$AZ$5:$AZ$41,$BH5))),"")) -> 270 | G5: =IF($BJ5>0,IF(INDEX('Final Calculation Sheet'!$E$4:$E$40,$BJ5-3)="","",INDEX('Final Calculation Sheet'!$E$4:$E$40,$BJ5-3)),IF(OR($BI5=1,$BL5=1,$BH5>0),"–","")) -> NO | H5: =IF($BJ5>0,IF(INDEX('Final Calculation Sheet'!$C$4:$C$40,$BJ5-3)="","",INDEX('Final Calculation Sheet'!$C$4:$C$40,$BJ5-3)),IF(OR($BI5=1,$BL5=1,$BH5>0),"–","")) -> 580 | I5: =IF($BJ5>0,IF(INDEX('Final Calculation Sheet'!$H$4:$H$40,$BJ5-3)="","",INDEX('Final Calculation Sheet'!$H$4:$H$40,$BJ5-3)),IF(OR($BI5=1,$BL5=1,$BH5>0),IF($BI5=1,SUM('Final Calculation Sheet'!$H$4:$H$40),IF($BL5=1,SUM('Final Calculation Sheet'!$H$4:$H$40)-SUMIFS('Final Calculation Sheet'!$H$4:$H$40,$AZ$5:$AZ$41,10),SUMIFS('Final Calculation Sheet'!$H$4:$H$40,$AZ$5:$AZ$41,$BH5))),"")) -> 156600 | J5: =IF($BJ5>0,IF(INDEX('Final Calculation Sheet'!$I$4:$I$40,$BJ5-3)="","",INDEX('Final Calculation Sheet'!$I$4:$I$40,$BJ5-3)),IF(OR($BI5=1,$BL5=1,$BH5>0),IF($BI5=1,SUM('Final Calculation Sheet'!$I$4:$I$40),IF($BL5=1,SUM('Final Calculation Sheet'!$I$4:$I$40)-SUMIFS('Final Calculation Sheet'!$I$4:$I$40,$AZ$5:$AZ$41,10),SUMIFS('Final Calculation Sheet'!$I$4:$I$40,$AZ$5:$AZ$41,$BH5))),"")) -> 28188 | K5: =IF($BJ5>0,IF(INDEX('Final Calculation Sheet'!$J$4:$J$40,$BJ5-3)="","",INDEX('Final Calculation Sheet'!$J$4:$J$40,$BJ5-3)),IF(OR($BI5=1,$BL5=1,$BH5>0),IF($BI5=1,SUM('Final Calculation Sheet'!$J$4:$J$40),IF($BL5=1,SUM('Final Calculation Sheet'!$J$4:$J$40)-SUMIFS('Final Calculation Sheet'!$J$4:$J$40,$AZ$5:$AZ$41,10),SUMIFS('Final Calculation Sheet'!$J$4:$J$40,$AZ$5:$AZ$41,$BH5))),"")) -> 184788 | L5: =IF($BJ5>0,IF(INDEX('Final Calculation Sheet'!$K$4:$K$40,$BJ5-3)="","",INDEX('Final Calculation Sheet'!$K$4:$K$40,$BJ5-3)),IF(OR($BI5=1,$BL5=1,$BH5>0),IF($BI5=1,SUM('Final Calculation Sheet'!$K$4:$K$40),IF($BL5=1,SUM('Final Calculation Sheet'!$K$4:$K$40)-SUMIFS('Final Calculation Sheet'!$K$4:$K$40,$AZ$5:$AZ$41,10),SUMIFS('Final Calculation Sheet'!$K$4:$K$40,$AZ$5:$AZ$41,$BH5))),"")) -> 3696 | M5: =IF($BJ5>0,IF(INDEX('Final Calculation Sheet'!$L$4:$L$40,$BJ5-3)="","",INDEX('Final Calculation Sheet'!$L$4:$L$40,$BJ5-3)),IF(OR($BI5=1,$BL5=1,$BH5>0),IF($BI5=1,SUM('Final Calculation Sheet'!$L$4:$L$40),IF($BL5=1,SUM('Final Calculation Sheet'!$L$4:$L$40)-SUMIFS('Final Calculation Sheet'!$L$4:$L$40,$AZ$5:$AZ$41,10),SUMIFS('Final Calculation Sheet'!$L$4:$L$40,$AZ$5:$AZ$41,$BH5))),"")) -> 156.6 | N5: =IF($BJ5>0,IF(INDEX('Final Calculation Sheet'!$M$4:$M$40,$BJ5-3)="","",INDEX('Final Calculation Sheet'!$M$4:$M$40,$BJ5-3)),IF(OR($BI5=1,$BL5=1,$BH5>0),IF($BI5=1,SUM('Final Calculation Sheet'!$M$4:$M$40),IF($BL5=1,SUM('Final Calculation Sheet'!$M$4:$M$40)-SUMIFS('Final Calculation Sheet'!$M$4:$M$40,$AZ$5:$AZ$41,10),SUMIFS('Final Calculation Sheet'!$M$4:$M$40,$AZ$5:$AZ$41,$BH5))),"")) -> 4157.73 | O5: =IF($BJ5>0,IF(INDEX('Final Calculation Sheet'!$N$4:$N$40,$BJ5-3)="","",INDEX('Final Calculation Sheet'!$N$4:$N$40,$BJ5-3)),IF(OR($BI5=1,$BL5=1,$BH5>0),IF($BI5=1,SUM('Final Calculation Sheet'!$N$4:$N$40),IF($BL5=1,SUM('Final Calculation Sheet'!$N$4:$N$40)-SUMIFS('Final Calculation Sheet'!$N$4:$N$40,$AZ$5:$AZ$41,10),SUMIFS('Final Calculation Sheet'!$N$4:$N$40,$AZ$5:$AZ$41,$BH5))),"")) -> 70.47 | P5: =IF($BJ5>0,IF(INDEX('Final Calculation Sheet'!$O$4:$O$40,$BJ5-3)="","",INDEX('Final Calculation Sheet'!$O$4:$O$40,$BJ5-3)),IF(OR($BI5=1,$BL5=1,$BH5>0),IF($BI5=1,SUM('Final Calculation Sheet'!$O$4:$O$40),IF($BL5=1,SUM('Final Calculation Sheet'!$O$4:$O$40)-SUMIFS('Final Calculation Sheet'!$O$4:$O$40,$AZ$5:$AZ$41,10),SUMIFS('Final Calculation Sheet'!$O$4:$O$40,$AZ$5:$AZ$41,$BH5))),"")) -> 4087.26 | Q5: =IF($BJ5>0,IF(INDEX('Final Calculation Sheet'!$P$4:$P$40,$BJ5-3)="","",INDEX('Final Calculation Sheet'!$P$4:$P$40,$BJ5-3)),IF(OR($BI5=1,$BL5=1,$BH5>0),IF($BI5=1,SUM('Final Calculation Sheet'!$P$4:$P$40),IF($BL5=1,SUM('Final Calculation Sheet'!$P$4:$P$40)-SUMIFS('Final Calculation Sheet'!$P$4:$P$40,$AZ$5:$AZ$41,10),SUMIFS('Final Calculation Sheet'!$P$4:$P$40,$AZ$5:$AZ$41,$BH5))),"")) -> 4244 | R5: =IF($BJ5>0,IF(INDEX('Final Calculation Sheet'!$Q$4:$Q$40,$BJ5-3)="","",INDEX('Final Calculation Sheet'!$Q$4:$Q$40,$BJ5-3)),IF(OR($BI5=1,$BL5=1,$BH5>0),"–","")) -> 0 | S5: =IF($BJ5>0,IF(INDEX('Final Calculation Sheet'!$R$4:$R$40,$BJ5-3)="","",INDEX('Final Calculation Sheet'!$R$4:$R$40,$BJ5-3)),IF(OR($BI5=1,$BL5=1,$BH5>0),IF($BI5=1,SUM('Final Calculation Sheet'!$R$4:$R$40),IF($BL5=1,SUM('Final Calculation Sheet'!$R$4:$R$40)-SUMIFS('Final Calculation Sheet'!$R$4:$R$40,$AZ$5:$AZ$41,10),SUMIFS('Final Calculation Sheet'!$R$4:$R$40,$AZ$5:$AZ$41,$BH5))),"")) -> 0 | T5: =IF($BJ5>0,IF(INDEX('Final Calculation Sheet'!$S$4:$S$40,$BJ5-3)="","",INDEX('Final Calculation Sheet'!$S$4:$S$40,$BJ5-3)),IF(OR($BI5=1,$BL5=1,$BH5>0),IF($BI5=1,SUM('Final Calculation Sheet'!$S$4:$S$40),IF($BL5=1,SUM('Final Calculation Sheet'!$S$4:$S$40)-SUMIFS('Final Calculation Sheet'!$S$4:$S$40,$AZ$5:$AZ$41,10),SUMIFS('Final Calculation Sheet'!$S$4:$S$40,$AZ$5:$AZ$41,$BH5))),"")) -> 184240 | U5: =IF($BJ5>0,IF(INDEX('Final Calculation Sheet'!$T$4:$T$40,$BJ5-3)="","",INDEX('Final Calculation Sheet'!$T$4:$T$40,$BJ5-3)),IF(OR($BI5=1,$BL5=1,$BH5>0),IF($BI5=1,SUM('Final Calculation Sheet'!$T$4:$T$40),IF($BL5=1,SUM('Final Calculation Sheet'!$T$4:$T$40)-SUMIFS('Final Calculation Sheet'!$T$4:$T$40,$AZ$5:$AZ$41,10),SUMIFS('Final Calculation Sheet'!$T$4:$T$40,$AZ$5:$AZ$41,$BH5))),"")) -> 39150 | V5: =IF($BJ5>0,IF(INDEX('Final Calculation Sheet'!$U$4:$U$40,$BJ5-3)="","",INDEX('Final Calculation Sheet'!$U$4:$U$40,$BJ5-3)),IF(OR($BI5=1,$BL5=1,$BH5>0),IF($BI5=1,SUM('Final Calculation Sheet'!$U$4:$U$40),IF($BL5=1,SUM('Final Calculation Sheet'!$U$4:$U$40)-SUMIFS('Final Calculation Sheet'!$U$4:$U$40,$AZ$5:$AZ$41,10),SUMIFS('Final Calculation Sheet'!$U$4:$U$40,$AZ$5:$AZ$41,$BH5))),"")) -> 39150 | W5: =IF($BJ5>0,IF(INDEX('Final Calculation Sheet'!$V$4:$V$40,$BJ5-3)="","",INDEX('Final Calculation Sheet'!$V$4:$V$40,$BJ5-3)),IF(OR($BI5=1,$BL5=1,$BH5>0),"–","")) -> 13.08.2026 | X5: =IF($BJ5>0,IF(INDEX('Final Calculation Sheet'!$W$4:$W$40,$BJ5-3)="","",INDEX('Final Calculation Sheet'!$W$4:$W$40,$BJ5-3)),IF(OR($BI5=1,$BL5=1,$BH5>0),IF($BI5=1,SUM('Final Calculation Sheet'!$W$4:$W$40),IF($BL5=1,SUM('Final Calculation Sheet'!$W$4:$W$40)-SUMIFS('Final Calculation Sheet'!$W$4:$W$40,$AZ$5:$AZ$41,10),SUMIFS('Final Calculation Sheet'!$W$4:$W$40,$AZ$5:$AZ$41,$BH5))),"")) -> 145090 | Y5: =IF($BJ5>0,IF(INDEX('Final Calculation Sheet'!$X$4:$X$40,$BJ5-3)="","",INDEX('Final Calculation Sheet'!$X$4:$X$40,$BJ5-3)),IF(OR($BI5=1,$BL5=1,$BH5>0),IF($BI5=1,SUM('Final Calculation Sheet'!$X$4:$X$40),IF($BL5=1,SUM('Final Calculation Sheet'!$X$4:$X$40)-SUMIFS('Final Calculation Sheet'!$X$4:$X$40,$AZ$5:$AZ$41,10),SUMIFS('Final Calculation Sheet'!$X$4:$X$40,$AZ$5:$AZ$41,$BH5))),"")) -> 145090 | Z5: =IF($BJ5>0,IF(INDEX('Final Calculation Sheet'!$Y$4:$Y$40,$BJ5-3)="","",INDEX('Final Calculation Sheet'!$Y$4:$Y$40,$BJ5-3)),IF(OR($BI5=1,$BL5=1,$BH5>0),"–","")) -> 24.08.2026 | AA5: =IF($BJ5>0,IF(INDEX('Final Calculation Sheet'!$Z$4:$Z$40,$BJ5-3)="","",INDEX('Final Calculation Sheet'!$Z$4:$Z$40,$BJ5-3)),IF(OR($BI5=1,$BL5=1,$BH5>0),IF($BI5=1,SUM('Final Calculation Sheet'!$Z$4:$Z$40),IF($BL5=1,SUM('Final Calculation Sheet'!$Z$4:$Z$40)-SUMIFS('Final Calculation Sheet'!$Z$4:$Z$40,$AZ$5:$AZ$41,10),SUMIFS('Final Calculation Sheet'!$Z$4:$Z$40,$AZ$5:$AZ$41,$BH5))),"")) -> 0 | AB5: =IF($BJ5>0,IF(INDEX('Final Calculation Sheet'!$AA$4:$AA$40,$BJ5-3)="","",INDEX('Final Calculation Sheet'!$AA$4:$AA$40,$BJ5-3)),IF(OR($BI5=1,$BL5=1,$BH5>0),IF($BI5=1,SUM('Final Calculation Sheet'!$AA$4:$AA$40),IF($BL5=1,SUM('Final Calculation Sheet'!$AA$4:$AA$40)-SUMIFS('Final Calculation Sheet'!$AA$4:$AA$40,$AZ$5:$AZ$41,10),SUMIFS('Final Calculation Sheet'!$AA$4:$AA$40,$AZ$5:$AZ$41,$BH5))),"")) | AC5: =IF($BJ5>0,IF(INDEX('Final Calculation Sheet'!$AB$4:$AB$40,$BJ5-3)="","",INDEX('Final Calculation Sheet'!$AB$4:$AB$40,$BJ5-3)),IF(OR($BI5=1,$BL5=1,$BH5>0),"–","")) | AD5: =IF($BJ5>0,IF(INDEX('Final Calculation Sheet'!$AC$4:$AC$40,$BJ5-3)="","",INDEX('Final Calculation Sheet'!$AC$4:$AC$40,$BJ5-3)),IF(OR($BI5=1,$BL5=1,$BH5>0),IF($BI5=1,SUM('Final Calculation Sheet'!$AC$4:$AC$40),IF($BL5=1,SUM('Final Calculation Sheet'!$AC$4:$AC$40)-SUMIFS('Final Calculation Sheet'!$AC$4:$AC$40,$AZ$5:$AZ$41,10),SUMIFS('Final Calculation Sheet'!$AC$4:$AC$40,$AZ$5:$AZ$41,$BH5))),"")) -> 184240 | AE5: =IF($BJ5>0,IF(INDEX('Final Calculation Sheet'!$AD$4:$AD$40,$BJ5-3)="","",INDEX('Final Calculation Sheet'!$AD$4:$AD$40,$BJ5-3)),IF(OR($BI5=1,$BL5=1,$BH5>0),IF($BI5=1,SUM('Final Calculation Sheet'!$AD$4:$AD$40),IF($BL5=1,SUM('Final Calculation Sheet'!$AD$4:$AD$40)-SUMIFS('Final Calculation Sheet'!$AD$4:$AD$40,$AZ$5:$AZ$41,10),SUMIFS('Final Calculation Sheet'!$AD$4:$AD$40,$AZ$5:$AZ$41,$BH5))),"")) -> 0 | AF5: =IF($BJ5>0,IF(INDEX('Final Calculation Sheet'!$AE$4:$AE$40,$BJ5-3)="","",INDEX('Final Calculation Sheet'!$AE$4:$AE$40,$BJ5-3)),IF(OR($BI5=1,$BL5=1,$BH5>0),"–","")) -> DR2640100030 | AG5: =IF($BJ5>0,IF(INDEX('Final Calculation Sheet'!$AF$4:$AF$40,$BJ5-3)="","",INDEX('Final Calculation Sheet'!$AF$4:$AF$40,$BJ5-3)),IF(OR($BI5=1,$BL5=1,$BH5>0),"–","")) -> 1800003302 | AH5: =IF($BJ5>0,IF(INDEX('Final Calculation Sheet'!$AG$4:$AG$40,$BJ5-3)="","",INDEX('Final Calculation Sheet'!$AG$4:$AG$40,$BJ5-3)),IF(OR($BI5=1,$BL5=1,$BH5>0),"–","")) -> 27.08.2026 | AI5: =IF($BJ5>0,IF(INDEX('Final Calculation Sheet'!$AD$4:$AD$40,$BJ5-3)="","",IF(INDEX('Final Calculation Sheet'!$AD$4:$AD$40,$BJ5-3)<=0,"SETTLED","OUTSTANDING")),IF(OR($BI5=1,$BL5=1,$BH5>0),IF(IF($BI5=1,SUM('Final Calculation Sheet'!$AD$4:$AD$40),IF($BL5=1,SUM('Final Calculation Sheet'!$AD$4:$AD$40)-SUMIFS('Final Calculation Sheet'!$AD$4:$AD$40,$AZ$5:$AZ$41,10),SUMIFS('Final Calculation Sheet'!$AD$4:$AD$40,$AZ$5:$AZ$41,$BH5)))<=0,"ALL SETTLED","OUTSTANDING"),"")) -> SETTLED | AK5: =IF($F$3="Lot No.",'Final Calculation Sheet'!$F$4,IF($F$3="Buyer",'Final Calculation Sheet'!$G$4,IF($F$3="Lot Name",'Final Calculation Sheet'!$B$4,IF($F$3="Bid Sheet",'Final Calculation Sheet'!$D$4,IF($F$3="Unit",'Final Calculation Sheet'!$E$4,'Final Calculation Sheet'!$F$4&" "&'Final Calculation Sheet'!$G$4&" "&'Final Calculation Sheet'!$B$4))))) -> 1763 AL HAMD TRADE CORPORATION Lot No. | AM5: =IF($B$3="",1,IF(AND(IF(COUNTIF($AR$9:$AY$9,1)=0,TRUE,SUMPRODUCT(($AR$9:$AY$9=1)*($AR$6:$AY$6<>"")*ISNUMBER(SEARCH($AR$6:$AY$6,$AK5)))>0),IF(COUNTIF($AR$9:$AY$9,2)=0,TRUE,SUMPRODUCT(($AR$9:$AY$9=2)*($AR$6:$AY$6<>"")*ISNUMBER(SEARCH($AR$6:$AY$6,$AK5)))>0),IF(COUNTIF($AR$9:$AY$9,3)=0,TRUE,SUMPRODUCT(($AR$9:$AY$9=3)*($AR$6:$AY$6<>"")*ISNUMBER(SEARCH($AR$6:$AY$6,$AK5)))>0),IF(COUNTIF($AR$9:$AY$9,4)=0,TRUE,SUMPRODUCT(($AR$9:$AY$9=4)*($AR$6:$AY$6<>"")*ISNUMBER(SEARCH($AR$6:$AY$6,$AK5)))>0),IF(COUNTIF($AR$9:$AY$9,5)=0,TRUE,SUMPRODUCT(($AR$9:$AY$9=5)*($AR$6:$AY$6<>"")*ISNUMBER(SEARCH($AR$6:$AY$6,$AK5)))>0),IF(COUNTIF($AR$9:$AY$9,6)=0,TRUE,SUMPRODUCT(($AR$9:$AY$9=6)*($AR$6:$AY$6<>"")*ISNUMBER(SEARCH($AR$6:$AY$6,$AK5)))>0),IF(COUNTIF($AR$9:$AY$9,7)=0,TRUE,SUMPRODUCT(($AR$9:$AY$9=7)*($AR$6:$AY$6<>"")*ISNUMBER(SEARCH($AR$6:$AY$6,$AK5)))>0),IF(COUNTIF($AR$9:$AY$9,8)=0,TRUE,SUMPRODUCT(($AR$9:$AY$9=8)*($AR$6:$AY$6<>"")*ISNUMBER(SEARCH($AR$6:$AY$6,$AK5)))>0)),1,0)) -> 0 | AO5: Lot No. | AR5: =IF($AR$4="",99999,MIN(IFERROR(FIND(",",$AR$4),99999),IFERROR(FIND("+",$AR$4),99999))) -> 5 | AS5: =IF($AS$4="",99999,MIN(IFERROR(FIND(",",$AS$4),99999),IFERROR(FIND("+",$AS$4),99999))) -> 99999 | AT5: =IF($AT$4="",99999,MIN(IFERROR(FIND(",",$AT$4),99999),IFERROR(FIND("+",$AT$4),99999))) -> 99999 | AU5: =IF($AU$4="",99999,MIN(IFERROR(FIND(",",$AU$4),99999),IFERROR(FIND("+",$AU$4),99999))) -> 99999 | AV5: =IF($AV$4="",99999,MIN(IFERROR(FIND(",",$AV$4),99999),IFERROR(FIND("+",$AV$4),99999))) -> 99999 | AW5: =IF($AW$4="",99999,MIN(IFERROR(FIND(",",$AW$4),99999),IFERROR(FIND("+",$AW$4),99999))) -> 99999 | AX5: =IF($AX$4="",99999,MIN(IFERROR(FIND(",",$AX$4),99999),IFERROR(FIND("+",$AX$4),99999))) -> 99999 | AY5: =IF($AY$4="",99999,MIN(IFERROR(FIND(",",$AY$4),99999),IFERROR(FIND("+",$AY$4),99999))) -> 99999 | AZ5: =IF($B$3="",9,IF($AM5=0,10,IF(AND($AR$6<>"",ISNUMBER(SEARCH($AR$6,$AK5))),1,IF(AND($AS$6<>"",ISNUMBER(SEARCH($AS$6,$AK5))),2,IF(AND($AT$6<>"",ISNUMBER(SEARCH($AT$6,$AK5))),3,IF(AND($AU$6<>"",ISNUMBER(SEARCH($AU$6,$AK5))),4,IF(AND($AV$6<>"",ISNUMBER(SEARCH($AV$6,$AK5))),5,IF(AND($AW$6<>"",ISNUMBER(SEARCH($AW$6,$AK5))),6,IF(AND($AX$6<>"",ISNUMBER(SEARCH($AX$6,$AK5))),7,IF(AND($AY$6<>"",ISNUMBER(SEARCH($AY$6,$AK5))),8,0)))))))))) -> 10 | BA5: =SUMPRODUCT(($AZ$5:$AZ$41=$AZ5)*($BC$5:$BC$41<$BC5))+1 -> 1 | BB5: =IF(INDEX($BF$4:$BF$13,$AZ5)=0,0,INDEX($BE$4:$BE$13,$AZ5)+$BA5-1) -> 17 | BC5: 4 | BD5: =COUNTIF($AZ$5:$AZ$41,2) -> 5 | BE5: =IF($BD4=0,$BE4,$BF4+1) -> 10 | BF5: =IF($BD5=0,0,$BE5+$BD5) -> 15 | BG5: =IF($BD13=0,$BE13,$BF13+1) -> 46 | BH5: =IFERROR(MATCH(5,$BF$4:$BF$13,0),0) -> 0 | BI5: =IF(5=$BG$5,1,0) -> 0 | BJ5: =IF(OR($BH5>0,$BI5=1,$BL5=1),0,IFERROR(INDEX($BC$5:$BC$41,MATCH(5,$BB$5:$BB$41,0)),0)) -> 5 | BK5: =IF($BJ5>0,IF(INDEX($AZ$5:$AZ$41,MATCH(5,$BB$5:$BB$41,0))=10,1,0),IF($BH5=10,1,0)) -> 0 | BL5: =IF(5=$BG$4,1,0) -> 0
